/var/spool/slurmd/job53796/slurm_script: line 11: cd: SSL_VAN: No such file or directory

----------------------------------------------------------------------------
  cuda:
----------------------------------------------------------------------------
     Versions:
        cuda/10.2
        cuda/11.0
        cuda/11.2
        cuda/11.3
        cuda/11.4
        cuda/11.5
        cuda/11.6
        cuda/12.0

----------------------------------------------------------------------------
  For detailed information about a specific "cuda" package (including how to load the modules) use the module's full name.
  Note that names that have a trailing (E) are extensions provided by other modules.
  For example:

     $ module spider cuda/12.0
----------------------------------------------------------------------------

 


CommandNotFoundError: Your shell has not been properly configured to use 'conda activate'.
To initialize your shell, run

    $ conda init <SHELL_NAME>

Currently supported shells are:
  - bash
  - fish
  - tcsh
  - xonsh
  - zsh
  - powershell

See 'conda init --help' for more information and options.

IMPORTANT: You may need to close and restart your shell after running 'conda init'.


/home/karimimonsefi.1/miniconda3/lib/python3.9/site-packages/mmcv/__init__.py:20: UserWarning: On January 1, 2023, MMCV will release v2.0.0, in which it will remove components related to the training process and add a data transformation module. In addition, it will rename the package names mmcv to mmcv-lite and mmcv-full to mmcv. See https://github.com/open-mmlab/mmcv/blob/master/docs/en/compatibility.md for more details.
  warnings.warn(
/home/karimimonsefi.1/SSL_VAN/BTCV/main.py:106: UserWarning: Found total gpus 2
  warnings.warn("Found total gpus {}".format(args.ngpus_per_node))
/home/karimimonsefi.1/miniconda3/lib/python3.9/site-packages/mmcv/__init__.py:20: UserWarning: On January 1, 2023, MMCV will release v2.0.0, in which it will remove components related to the training process and add a data transformation module. In addition, it will rename the package names mmcv to mmcv-lite and mmcv-full to mmcv. See https://github.com/open-mmlab/mmcv/blob/master/docs/en/compatibility.md for more details.
  warnings.warn(
/home/karimimonsefi.1/miniconda3/lib/python3.9/site-packages/mmcv/__init__.py:20: UserWarning: On January 1, 2023, MMCV will release v2.0.0, in which it will remove components related to the training process and add a data transformation module. In addition, it will rename the package names mmcv to mmcv-lite and mmcv-full to mmcv. See https://github.com/open-mmlab/mmcv/blob/master/docs/en/compatibility.md for more details.
  warnings.warn(
/home/karimimonsefi.1/SSL_VAN/BTCV/main.py:213: UserWarning: 0 gpu 0
  warnings.warn(f"{args.rank} gpu {args.gpu}")
/home/karimimonsefi.1/SSL_VAN/BTCV/main.py:215: UserWarning: Batch size is: 2 epochs 15000
  warnings.warn(f"Batch size is: {args.batch_size} epochs {args.max_epochs}")
/home/karimimonsefi.1/SSL_VAN/BTCV/main.py:213: UserWarning: 1 gpu 1
  warnings.warn(f"{args.rank} gpu {args.gpu}")
/home/karimimonsefi.1/miniconda3/lib/python3.9/site-packages/monai/transforms/post/array.py:176: UserWarning: `to_onehot=True/False` is deprecated, please use `to_onehot=num_classes` instead.
  warnings.warn("`to_onehot=True/False` is deprecated, please use `to_onehot=num_classes` instead.")
/home/karimimonsefi.1/SSL_VAN/BTCV/main.py:281: UserWarning: Total parameters count 74849012
  warnings.warn(f"Total parameters count {pytorch_total_params}")
/home/karimimonsefi.1/SSL_VAN/BTCV/main.py:284: UserWarning: Total args.checkpoint True
  warnings.warn(f"Total args.checkpoint {args.checkpoint}")
/home/karimimonsefi.1/SSL_VAN/BTCV/main.py:291: UserWarning:  Best url model is 64-128-256_3-4-3_6-6-4_vae___VANV4GLV2_2__best.pt, final model url is 64-128-256_3-4-3_6-6-4_vae___VANV4GLV2_2__final.pt
  warnings.warn(f" Best url model is {args.best_model_url}, final model url is {args.final_model_url}")
/home/karimimonsefi.1/miniconda3/lib/python3.9/site-packages/monai/transforms/post/array.py:176: UserWarning: `to_onehot=True/False` is deprecated, please use `to_onehot=num_classes` instead.
  warnings.warn("`to_onehot=True/False` is deprecated, please use `to_onehot=num_classes` instead.")
/home/karimimonsefi.1/SSL_VAN/BTCV/main.py:281: UserWarning: Total parameters count 74849012
  warnings.warn(f"Total parameters count {pytorch_total_params}")
/home/karimimonsefi.1/SSL_VAN/BTCV/main.py:284: UserWarning: Total args.checkpoint True
  warnings.warn(f"Total args.checkpoint {args.checkpoint}")
/home/karimimonsefi.1/SSL_VAN/BTCV/main.py:291: UserWarning:  Best url model is 64-128-256_3-4-3_6-6-4_vae___VANV4GLV2_2__best.pt, final model url is 64-128-256_3-4-3_6-6-4_vae___VANV4GLV2_2__final.pt
  warnings.warn(f" Best url model is {args.best_model_url}, final model url is {args.final_model_url}")
/home/karimimonsefi.1/SSL_VAN/BTCV/main.py:307: UserWarning: => loaded checkpoint 'True' (epoch 253) (bestacc 0.32929518818855286)
  warnings.warn("=> loaded checkpoint '{}' (epoch {}) (bestacc {})".format(
/home/karimimonsefi.1/SSL_VAN/BTCV/main.py:307: UserWarning: => loaded checkpoint 'True' (epoch 253) (bestacc 0.32929518818855286)
  warnings.warn("=> loaded checkpoint '{}' (epoch {}) (bestacc {})".format(
/home/karimimonsefi.1/SSL_VAN/BTCV/trainer.py:140: UserWarning: Writing Tensorboard logs to ./runs/BTCV/test_log
  warnings.warn(f"Writing Tensorboard logs to {args.logdir}")
/home/karimimonsefi.1/SSL_VAN/BTCV/trainer.py:148: UserWarning: 0  Tue May  9 08:03:42 2023  Epoch: 253
  warnings.warn(f"{args.rank}  {time.ctime()}  Epoch: {epoch}")
/home/karimimonsefi.1/SSL_VAN/BTCV/trainer.py:148: UserWarning: 1  Tue May  9 08:03:42 2023  Epoch: 253
  warnings.warn(f"{args.rank}  {time.ctime()}  Epoch: {epoch}")
input_list/dataset_BTCV_List.json
input_list/dataset_BTCV_List.json
Traceback (most recent call last):
  File "/home/karimimonsefi.1/SSL_VAN/BTCV/main.py", line 369, in <module>
    main()
  File "/home/karimimonsefi.1/SSL_VAN/BTCV/main.py", line 108, in main
    mp.spawn(main_worker, nprocs=args.ngpus_per_node, args=(args,))
  File "/home/karimimonsefi.1/miniconda3/lib/python3.9/site-packages/torch/multiprocessing/spawn.py", line 240, in spawn
    return start_processes(fn, args, nprocs, join, daemon, start_method='spawn')
  File "/home/karimimonsefi.1/miniconda3/lib/python3.9/site-packages/torch/multiprocessing/spawn.py", line 198, in start_processes
    while not context.join():
  File "/home/karimimonsefi.1/miniconda3/lib/python3.9/site-packages/torch/multiprocessing/spawn.py", line 160, in join
    raise ProcessRaisedException(msg, error_index, failed_process.pid)
torch.multiprocessing.spawn.ProcessRaisedException: 

-- Process 0 terminated with the following error:
Traceback (most recent call last):
  File "/home/karimimonsefi.1/miniconda3/lib/python3.9/site-packages/torch/multiprocessing/spawn.py", line 69, in _wrap
    fn(i, *args)
  File "/home/karimimonsefi.1/SSL_VAN/BTCV/main.py", line 347, in main_worker
    accuracy = run_training(
  File "/home/karimimonsefi.1/SSL_VAN/BTCV/trainer.py", line 150, in run_training
    train_loss = train_epoch(
  File "/home/karimimonsefi.1/SSL_VAN/BTCV/trainer.py", line 26, in train_epoch
    for idx, batch_data in enumerate(loader):
  File "/home/karimimonsefi.1/miniconda3/lib/python3.9/site-packages/torch/utils/data/dataloader.py", line 628, in __next__
    data = self._next_data()
  File "/home/karimimonsefi.1/miniconda3/lib/python3.9/site-packages/torch/utils/data/dataloader.py", line 1333, in _next_data
    return self._process_data(data)
  File "/home/karimimonsefi.1/miniconda3/lib/python3.9/site-packages/torch/utils/data/dataloader.py", line 1359, in _process_data
    data.reraise()
  File "/home/karimimonsefi.1/miniconda3/lib/python3.9/site-packages/torch/_utils.py", line 543, in reraise
    raise exception
RuntimeError: Caught RuntimeError in DataLoader worker process 0.
Original Traceback (most recent call last):
  File "/home/karimimonsefi.1/miniconda3/lib/python3.9/site-packages/nibabel/loadsave.py", line 87, in load
    stat_result = os.stat(filename)
FileNotFoundError: [Errno 2] No such file or directory: '../images/BTCV/Abdomen/RawData/Trainicng/img/img0022.nii.gz'

During handling of the above exception, another exception occurred:

Traceback (most recent call last):
  File "/home/karimimonsefi.1/miniconda3/lib/python3.9/site-packages/monai/transforms/transform.py", line 89, in apply_transform
    return _apply_transform(transform, data, unpack_items)
  File "/home/karimimonsefi.1/miniconda3/lib/python3.9/site-packages/monai/transforms/transform.py", line 53, in _apply_transform
    return transform(parameters)
  File "/home/karimimonsefi.1/miniconda3/lib/python3.9/site-packages/monai/transforms/io/dictionary.py", line 131, in __call__
    data = self._loader(d[key], reader)
  File "/home/karimimonsefi.1/miniconda3/lib/python3.9/site-packages/monai/transforms/io/array.py", line 213, in __call__
    img = reader.read(filename)
  File "/home/karimimonsefi.1/miniconda3/lib/python3.9/site-packages/monai/data/image_reader.py", line 421, in read
    img = nib.load(name, **kwargs_)
  File "/home/karimimonsefi.1/miniconda3/lib/python3.9/site-packages/nibabel/loadsave.py", line 89, in load
    raise FileNotFoundError(f"No such file or no access: '{filename}'")
FileNotFoundError: No such file or no access: '../images/BTCV/Abdomen/RawData/Trainicng/img/img0022.nii.gz'

The above exception was the direct cause of the following exception:

Traceback (most recent call last):
  File "/home/karimimonsefi.1/miniconda3/lib/python3.9/site-packages/monai/transforms/transform.py", line 89, in apply_transform
    return _apply_transform(transform, data, unpack_items)
  File "/home/karimimonsefi.1/miniconda3/lib/python3.9/site-packages/monai/transforms/transform.py", line 53, in _apply_transform
    return transform(parameters)
  File "/home/karimimonsefi.1/miniconda3/lib/python3.9/site-packages/monai/transforms/compose.py", line 173, in __call__
    input_ = apply_transform(_transform, input_, self.map_items, self.unpack_items, self.log_stats)
  File "/home/karimimonsefi.1/miniconda3/lib/python3.9/site-packages/monai/transforms/transform.py", line 113, in apply_transform
    raise RuntimeError(f"applying transform {transform}") from e
RuntimeError: applying transform <monai.transforms.io.dictionary.LoadImaged object at 0x14c1ddcab070>

The above exception was the direct cause of the following exception:

Traceback (most recent call last):
  File "/home/karimimonsefi.1/miniconda3/lib/python3.9/site-packages/torch/utils/data/_utils/worker.py", line 302, in _worker_loop
    data = fetcher.fetch(index)
  File "/home/karimimonsefi.1/miniconda3/lib/python3.9/site-packages/torch/utils/data/_utils/fetch.py", line 58, in fetch
    data = [self.dataset[idx] for idx in possibly_batched_index]
  File "/home/karimimonsefi.1/miniconda3/lib/python3.9/site-packages/torch/utils/data/_utils/fetch.py", line 58, in <listcomp>
    data = [self.dataset[idx] for idx in possibly_batched_index]
  File "/home/karimimonsefi.1/miniconda3/lib/python3.9/site-packages/monai/data/dataset.py", line 97, in __getitem__
    return self._transform(index)
  File "/home/karimimonsefi.1/miniconda3/lib/python3.9/site-packages/monai/data/dataset.py", line 83, in _transform
    return apply_transform(self.transform, data_i) if self.transform is not None else data_i
  File "/home/karimimonsefi.1/miniconda3/lib/python3.9/site-packages/monai/transforms/transform.py", line 113, in apply_transform
    raise RuntimeError(f"applying transform {transform}") from e
RuntimeError: applying transform <monai.transforms.compose.Compose object at 0x14c1ddca8280>


