/var/spool/slurmd/job50734/slurm_script: line 12: cd: SSL_VAN: No such file or directory

----------------------------------------------------------------------------
  cuda:
----------------------------------------------------------------------------
     Versions:
        cuda/10.2
        cuda/11.0
        cuda/11.2
        cuda/11.3
        cuda/11.4
        cuda/11.5
        cuda/11.6
        cuda/12.0

----------------------------------------------------------------------------
  For detailed information about a specific "cuda" package (including how to load the modules) use the module's full name.
  Note that names that have a trailing (E) are extensions provided by other modules.
  For example:

     $ module spider cuda/12.0
----------------------------------------------------------------------------

 


CommandNotFoundError: Your shell has not been properly configured to use 'conda activate'.
To initialize your shell, run

    $ conda init <SHELL_NAME>

Currently supported shells are:
  - bash
  - fish
  - tcsh
  - xonsh
  - zsh
  - powershell

See 'conda init --help' for more information and options.

IMPORTANT: You may need to close and restart your shell after running 'conda init'.


2023-04-28 10:33:35 | INFO | root | Namespace(a_min=-1000, a_max=1000, b_min=0.0, b_max=1.0, space_x=1.5, space_y=1.5, space_z=2.0, roi_x=96, roi_y=96, roi_z=96, num_workers=32, distributed=False, mode='server', num_samples=6, km_path='./cluster_models_1/cluster_model_1_{}_{}_{}.joblib', n_clusters=445, seed=42, init='k-means++', max_iter=250, batch_size=20, tol=0.0, max_no_improvement=100, n_init=50, reassignment_ratio=0.0)
Dataset 1 LUNA16: number of data: 842
Dataset 2 Covid 19: OK number of data: 722
Dataset 3 HNSCC: number of data: 954
Dataset 4 TCIA Colon: number of data: 1535
Dataset 5 TCIA LIDC: OK number of data: 450
Dataset all training: number of data: 1535
loader is ready
2023-04-28 10:34:55 | INFO | learn_kmeans | for batch number 0 the res size is 0
2023-04-28 10:40:55 | INFO | learn_kmeans | for batch number 1 the res size is 2304
2023-04-28 10:45:02 | INFO | learn_kmeans | for batch number 2 the res size is 3456
2023-04-28 10:45:18 | INFO | learn_kmeans | for batch number 3 the res size is 4608
2023-04-28 10:45:18 | INFO | learn_kmeans | for batch number 4 the res size is 5760
2023-04-28 10:45:18 | INFO | learn_kmeans | for batch number 5 the res size is 6912
2023-04-28 10:45:18 | INFO | learn_kmeans | for batch number 6 the res size is 8064
2023-04-28 10:45:18 | INFO | learn_kmeans | for batch number 7 the res size is 9216
2023-04-28 10:45:19 | INFO | learn_kmeans | for batch number 8 the res size is 10368
Traceback (most recent call last):
  File "/home/karimimonsefi.1/SSL_VAN/clustering/kmeans_learning.py", line 145, in <module>
    learn_kmeans(args)
  File "/home/karimimonsefi.1/SSL_VAN/clustering/kmeans_learning.py", line 73, in learn_kmeans
    feat = load_data(args)
  File "/home/karimimonsefi.1/SSL_VAN/clustering/kmeans_learning.py", line 50, in load_data
    for idx, batch_data in enumerate(training_loader):
  File "/home/karimimonsefi.1/miniconda3/lib/python3.9/site-packages/torch/utils/data/dataloader.py", line 628, in __next__
    data = self._next_data()
  File "/home/karimimonsefi.1/miniconda3/lib/python3.9/site-packages/torch/utils/data/dataloader.py", line 1313, in _next_data
    return self._process_data(data)
  File "/home/karimimonsefi.1/miniconda3/lib/python3.9/site-packages/torch/utils/data/dataloader.py", line 1359, in _process_data
    data.reraise()
  File "/home/karimimonsefi.1/miniconda3/lib/python3.9/site-packages/torch/_utils.py", line 543, in reraise
    raise exception
RuntimeError: Caught RuntimeError in DataLoader worker process 9.
Original Traceback (most recent call last):
  File "/home/karimimonsefi.1/miniconda3/lib/python3.9/site-packages/monai/transforms/transform.py", line 89, in apply_transform
    return _apply_transform(transform, data, unpack_items)
  File "/home/karimimonsefi.1/miniconda3/lib/python3.9/site-packages/monai/transforms/transform.py", line 53, in _apply_transform
    return transform(parameters)
  File "/home/karimimonsefi.1/miniconda3/lib/python3.9/site-packages/monai/transforms/io/dictionary.py", line 131, in __call__
    data = self._loader(d[key], reader)
  File "/home/karimimonsefi.1/miniconda3/lib/python3.9/site-packages/monai/transforms/io/array.py", line 240, in __call__
    img_array, meta_data = reader.get_data(img)
  File "/home/karimimonsefi.1/miniconda3/lib/python3.9/site-packages/monai/data/image_reader.py", line 450, in get_data
    data = self._get_array_data(i)
  File "/home/karimimonsefi.1/miniconda3/lib/python3.9/site-packages/monai/data/image_reader.py", line 522, in _get_array_data
    _array = np.array(img.get_fdata(dtype=self.dtype))
  File "/home/karimimonsefi.1/miniconda3/lib/python3.9/site-packages/nibabel/dataobj_images.py", line 368, in get_fdata
    data = np.asanyarray(self._dataobj, dtype=dtype)
  File "/home/karimimonsefi.1/miniconda3/lib/python3.9/site-packages/nibabel/arrayproxy.py", line 426, in __array__
    arr = self._get_scaled(dtype=dtype, slicer=())
  File "/home/karimimonsefi.1/miniconda3/lib/python3.9/site-packages/nibabel/arrayproxy.py", line 393, in _get_scaled
    scaled = apply_read_scaling(self._get_unscaled(slicer=slicer), scl_slope, scl_inter)
  File "/home/karimimonsefi.1/miniconda3/lib/python3.9/site-packages/nibabel/arrayproxy.py", line 363, in _get_unscaled
    return array_from_file(
  File "/home/karimimonsefi.1/miniconda3/lib/python3.9/site-packages/nibabel/volumeutils.py", line 454, in array_from_file
    n_read = infile.readinto(data_bytes)
  File "/home/karimimonsefi.1/miniconda3/lib/python3.9/gzip.py", line 300, in read
    return self._buffer.read(size)
  File "/home/karimimonsefi.1/miniconda3/lib/python3.9/_compression.py", line 68, in readinto
    data = self.read(len(byte_view))
  File "/home/karimimonsefi.1/miniconda3/lib/python3.9/gzip.py", line 506, in read
    raise EOFError("Compressed file ended before the "
EOFError: Compressed file ended before the end-of-stream marker was reached

The above exception was the direct cause of the following exception:

Traceback (most recent call last):
  File "/home/karimimonsefi.1/miniconda3/lib/python3.9/site-packages/monai/transforms/transform.py", line 89, in apply_transform
    return _apply_transform(transform, data, unpack_items)
  File "/home/karimimonsefi.1/miniconda3/lib/python3.9/site-packages/monai/transforms/transform.py", line 53, in _apply_transform
    return transform(parameters)
  File "/home/karimimonsefi.1/miniconda3/lib/python3.9/site-packages/monai/transforms/compose.py", line 173, in __call__
    input_ = apply_transform(_transform, input_, self.map_items, self.unpack_items, self.log_stats)
  File "/home/karimimonsefi.1/miniconda3/lib/python3.9/site-packages/monai/transforms/transform.py", line 113, in apply_transform
    raise RuntimeError(f"applying transform {transform}") from e
RuntimeError: applying transform <monai.transforms.io.dictionary.LoadImaged object at 0x152740174be0>

The above exception was the direct cause of the following exception:

Traceback (most recent call last):
  File "/home/karimimonsefi.1/miniconda3/lib/python3.9/site-packages/torch/utils/data/_utils/worker.py", line 302, in _worker_loop
    data = fetcher.fetch(index)
  File "/home/karimimonsefi.1/miniconda3/lib/python3.9/site-packages/torch/utils/data/_utils/fetch.py", line 58, in fetch
    data = [self.dataset[idx] for idx in possibly_batched_index]
  File "/home/karimimonsefi.1/miniconda3/lib/python3.9/site-packages/torch/utils/data/_utils/fetch.py", line 58, in <listcomp>
    data = [self.dataset[idx] for idx in possibly_batched_index]
  File "/home/karimimonsefi.1/miniconda3/lib/python3.9/site-packages/monai/data/dataset.py", line 97, in __getitem__
    return self._transform(index)
  File "/home/karimimonsefi.1/miniconda3/lib/python3.9/site-packages/monai/data/dataset.py", line 83, in _transform
    return apply_transform(self.transform, data_i) if self.transform is not None else data_i
  File "/home/karimimonsefi.1/miniconda3/lib/python3.9/site-packages/monai/transforms/transform.py", line 113, in apply_transform
    raise RuntimeError(f"applying transform {transform}") from e
RuntimeError: applying transform <monai.transforms.compose.Compose object at 0x15262c373100>

2023-04-28 10:45:43 | INFO | root | Namespace(a_min=-1000, a_max=1000, b_min=0.0, b_max=1.0, space_x=1.5, space_y=1.5, space_z=2.0, roi_x=96, roi_y=96, roi_z=96, num_workers=32, distributed=False, mode='server', num_samples=6, km_path='./cluster_models_1/cluster_model_1_{}_{}_{}.joblib', n_clusters=468, seed=42, init='k-means++', max_iter=250, batch_size=20, tol=0.0, max_no_improvement=100, n_init=50, reassignment_ratio=0.0)
Dataset 1 LUNA16: number of data: 842
Dataset 2 Covid 19: OK number of data: 722
Dataset 3 HNSCC: number of data: 954
Dataset 4 TCIA Colon: number of data: 1535
Dataset 5 TCIA LIDC: OK number of data: 450
Dataset all training: number of data: 1535
loader is ready
2023-04-28 10:49:38 | INFO | learn_kmeans | for batch number 0 the res size is 0
2023-04-28 10:49:38 | INFO | learn_kmeans | for batch number 1 the res size is 2304
2023-04-28 10:49:38 | INFO | learn_kmeans | for batch number 2 the res size is 3456
2023-04-28 10:52:46 | INFO | learn_kmeans | for batch number 3 the res size is 4608
2023-04-28 10:52:46 | INFO | learn_kmeans | for batch number 4 the res size is 5760
2023-04-28 10:56:39 | INFO | learn_kmeans | for batch number 5 the res size is 6912
2023-04-28 10:56:40 | INFO | learn_kmeans | for batch number 6 the res size is 8064
2023-04-28 10:56:40 | INFO | learn_kmeans | for batch number 7 the res size is 9216
2023-04-28 10:56:40 | INFO | learn_kmeans | for batch number 8 the res size is 10368
2023-04-28 10:56:40 | INFO | learn_kmeans | for batch number 9 the res size is 11520
2023-04-28 10:56:54 | INFO | learn_kmeans | for batch number 10 the res size is 12672
Traceback (most recent call last):
  File "/home/karimimonsefi.1/SSL_VAN/clustering/kmeans_learning.py", line 145, in <module>
    learn_kmeans(args)
  File "/home/karimimonsefi.1/SSL_VAN/clustering/kmeans_learning.py", line 73, in learn_kmeans
    feat = load_data(args)
  File "/home/karimimonsefi.1/SSL_VAN/clustering/kmeans_learning.py", line 50, in load_data
    for idx, batch_data in enumerate(training_loader):
  File "/home/karimimonsefi.1/miniconda3/lib/python3.9/site-packages/torch/utils/data/dataloader.py", line 628, in __next__
    data = self._next_data()
  File "/home/karimimonsefi.1/miniconda3/lib/python3.9/site-packages/torch/utils/data/dataloader.py", line 1313, in _next_data
    return self._process_data(data)
  File "/home/karimimonsefi.1/miniconda3/lib/python3.9/site-packages/torch/utils/data/dataloader.py", line 1359, in _process_data
    data.reraise()
  File "/home/karimimonsefi.1/miniconda3/lib/python3.9/site-packages/torch/_utils.py", line 543, in reraise
    raise exception
RuntimeError: Caught RuntimeError in DataLoader worker process 11.
Original Traceback (most recent call last):
  File "/home/karimimonsefi.1/miniconda3/lib/python3.9/site-packages/monai/transforms/transform.py", line 89, in apply_transform
    return _apply_transform(transform, data, unpack_items)
  File "/home/karimimonsefi.1/miniconda3/lib/python3.9/site-packages/monai/transforms/transform.py", line 53, in _apply_transform
    return transform(parameters)
  File "/home/karimimonsefi.1/miniconda3/lib/python3.9/site-packages/monai/transforms/io/dictionary.py", line 131, in __call__
    data = self._loader(d[key], reader)
  File "/home/karimimonsefi.1/miniconda3/lib/python3.9/site-packages/monai/transforms/io/array.py", line 240, in __call__
    img_array, meta_data = reader.get_data(img)
  File "/home/karimimonsefi.1/miniconda3/lib/python3.9/site-packages/monai/data/image_reader.py", line 450, in get_data
    data = self._get_array_data(i)
  File "/home/karimimonsefi.1/miniconda3/lib/python3.9/site-packages/monai/data/image_reader.py", line 522, in _get_array_data
    _array = np.array(img.get_fdata(dtype=self.dtype))
  File "/home/karimimonsefi.1/miniconda3/lib/python3.9/site-packages/nibabel/dataobj_images.py", line 368, in get_fdata
    data = np.asanyarray(self._dataobj, dtype=dtype)
  File "/home/karimimonsefi.1/miniconda3/lib/python3.9/site-packages/nibabel/arrayproxy.py", line 426, in __array__
    arr = self._get_scaled(dtype=dtype, slicer=())
  File "/home/karimimonsefi.1/miniconda3/lib/python3.9/site-packages/nibabel/arrayproxy.py", line 393, in _get_scaled
    scaled = apply_read_scaling(self._get_unscaled(slicer=slicer), scl_slope, scl_inter)
  File "/home/karimimonsefi.1/miniconda3/lib/python3.9/site-packages/nibabel/arrayproxy.py", line 363, in _get_unscaled
    return array_from_file(
  File "/home/karimimonsefi.1/miniconda3/lib/python3.9/site-packages/nibabel/volumeutils.py", line 454, in array_from_file
    n_read = infile.readinto(data_bytes)
  File "/home/karimimonsefi.1/miniconda3/lib/python3.9/gzip.py", line 300, in read
    return self._buffer.read(size)
  File "/home/karimimonsefi.1/miniconda3/lib/python3.9/_compression.py", line 68, in readinto
    data = self.read(len(byte_view))
  File "/home/karimimonsefi.1/miniconda3/lib/python3.9/gzip.py", line 506, in read
    raise EOFError("Compressed file ended before the "
EOFError: Compressed file ended before the end-of-stream marker was reached

The above exception was the direct cause of the following exception:

Traceback (most recent call last):
  File "/home/karimimonsefi.1/miniconda3/lib/python3.9/site-packages/monai/transforms/transform.py", line 89, in apply_transform
    return _apply_transform(transform, data, unpack_items)
  File "/home/karimimonsefi.1/miniconda3/lib/python3.9/site-packages/monai/transforms/transform.py", line 53, in _apply_transform
    return transform(parameters)
  File "/home/karimimonsefi.1/miniconda3/lib/python3.9/site-packages/monai/transforms/compose.py", line 173, in __call__
    input_ = apply_transform(_transform, input_, self.map_items, self.unpack_items, self.log_stats)
  File "/home/karimimonsefi.1/miniconda3/lib/python3.9/site-packages/monai/transforms/transform.py", line 113, in apply_transform
    raise RuntimeError(f"applying transform {transform}") from e
RuntimeError: applying transform <monai.transforms.io.dictionary.LoadImaged object at 0x153ff68dbbe0>

The above exception was the direct cause of the following exception:

Traceback (most recent call last):
  File "/home/karimimonsefi.1/miniconda3/lib/python3.9/site-packages/torch/utils/data/_utils/worker.py", line 302, in _worker_loop
    data = fetcher.fetch(index)
  File "/home/karimimonsefi.1/miniconda3/lib/python3.9/site-packages/torch/utils/data/_utils/fetch.py", line 58, in fetch
    data = [self.dataset[idx] for idx in possibly_batched_index]
  File "/home/karimimonsefi.1/miniconda3/lib/python3.9/site-packages/torch/utils/data/_utils/fetch.py", line 58, in <listcomp>
    data = [self.dataset[idx] for idx in possibly_batched_index]
  File "/home/karimimonsefi.1/miniconda3/lib/python3.9/site-packages/monai/data/dataset.py", line 97, in __getitem__
    return self._transform(index)
  File "/home/karimimonsefi.1/miniconda3/lib/python3.9/site-packages/monai/data/dataset.py", line 83, in _transform
    return apply_transform(self.transform, data_i) if self.transform is not None else data_i
  File "/home/karimimonsefi.1/miniconda3/lib/python3.9/site-packages/monai/transforms/transform.py", line 113, in apply_transform
    raise RuntimeError(f"applying transform {transform}") from e
RuntimeError: applying transform <monai.transforms.compose.Compose object at 0x153ee2b00e80>

2023-04-28 10:57:27 | INFO | root | Namespace(a_min=-1000, a_max=1000, b_min=0.0, b_max=1.0, space_x=1.5, space_y=1.5, space_z=2.0, roi_x=96, roi_y=96, roi_z=96, num_workers=32, distributed=False, mode='server', num_samples=6, km_path='./cluster_models_1/cluster_model_1_{}_{}_{}.joblib', n_clusters=169, seed=42, init='k-means++', max_iter=250, batch_size=20, tol=0.0, max_no_improvement=100, n_init=50, reassignment_ratio=0.0)
Dataset 1 LUNA16: number of data: 842
Dataset 2 Covid 19: OK number of data: 722
Dataset 3 HNSCC: number of data: 954
Dataset 4 TCIA Colon: number of data: 1535
Dataset 5 TCIA LIDC: OK number of data: 450
Dataset all training: number of data: 1535
loader is ready
2023-04-28 10:58:35 | INFO | learn_kmeans | for batch number 0 the res size is 0
2023-04-28 11:04:14 | INFO | learn_kmeans | for batch number 1 the res size is 2304
2023-04-28 11:05:43 | INFO | learn_kmeans | for batch number 2 the res size is 3456
2023-04-28 11:06:12 | INFO | learn_kmeans | for batch number 3 the res size is 4608
2023-04-28 11:06:13 | INFO | learn_kmeans | for batch number 4 the res size is 5760
2023-04-28 11:06:54 | INFO | learn_kmeans | for batch number 5 the res size is 6912
2023-04-28 11:06:55 | INFO | learn_kmeans | for batch number 6 the res size is 8064
2023-04-28 11:06:55 | INFO | learn_kmeans | for batch number 7 the res size is 9216
2023-04-28 11:07:31 | INFO | learn_kmeans | for batch number 8 the res size is 10368
2023-04-28 11:07:31 | INFO | learn_kmeans | for batch number 9 the res size is 11520
2023-04-28 11:07:31 | INFO | learn_kmeans | for batch number 10 the res size is 12672
2023-04-28 11:07:31 | INFO | learn_kmeans | for batch number 11 the res size is 13824
2023-04-28 11:07:31 | INFO | learn_kmeans | for batch number 12 the res size is 14976
2023-04-28 11:07:31 | INFO | learn_kmeans | for batch number 13 the res size is 16128
2023-04-28 11:07:31 | INFO | learn_kmeans | for batch number 14 the res size is 17280
2023-04-28 11:07:32 | INFO | learn_kmeans | for batch number 15 the res size is 18432
2023-04-28 11:07:32 | INFO | learn_kmeans | for batch number 16 the res size is 19584
2023-04-28 11:07:32 | INFO | learn_kmeans | for batch number 17 the res size is 20736
2023-04-28 11:07:32 | INFO | learn_kmeans | for batch number 18 the res size is 21888
2023-04-28 11:07:32 | INFO | learn_kmeans | for batch number 19 the res size is 23040
Traceback (most recent call last):
  File "/home/karimimonsefi.1/SSL_VAN/clustering/kmeans_learning.py", line 145, in <module>
    learn_kmeans(args)
  File "/home/karimimonsefi.1/SSL_VAN/clustering/kmeans_learning.py", line 73, in learn_kmeans
    feat = load_data(args)
  File "/home/karimimonsefi.1/SSL_VAN/clustering/kmeans_learning.py", line 50, in load_data
    for idx, batch_data in enumerate(training_loader):
  File "/home/karimimonsefi.1/miniconda3/lib/python3.9/site-packages/torch/utils/data/dataloader.py", line 628, in __next__
    data = self._next_data()
  File "/home/karimimonsefi.1/miniconda3/lib/python3.9/site-packages/torch/utils/data/dataloader.py", line 1313, in _next_data
    return self._process_data(data)
  File "/home/karimimonsefi.1/miniconda3/lib/python3.9/site-packages/torch/utils/data/dataloader.py", line 1359, in _process_data
    data.reraise()
  File "/home/karimimonsefi.1/miniconda3/lib/python3.9/site-packages/torch/_utils.py", line 543, in reraise
    raise exception
RuntimeError: Caught RuntimeError in DataLoader worker process 20.
Original Traceback (most recent call last):
  File "/home/karimimonsefi.1/miniconda3/lib/python3.9/site-packages/monai/transforms/transform.py", line 89, in apply_transform
    return _apply_transform(transform, data, unpack_items)
  File "/home/karimimonsefi.1/miniconda3/lib/python3.9/site-packages/monai/transforms/transform.py", line 53, in _apply_transform
    return transform(parameters)
  File "/home/karimimonsefi.1/miniconda3/lib/python3.9/site-packages/monai/transforms/io/dictionary.py", line 131, in __call__
    data = self._loader(d[key], reader)
  File "/home/karimimonsefi.1/miniconda3/lib/python3.9/site-packages/monai/transforms/io/array.py", line 240, in __call__
    img_array, meta_data = reader.get_data(img)
  File "/home/karimimonsefi.1/miniconda3/lib/python3.9/site-packages/monai/data/image_reader.py", line 450, in get_data
    data = self._get_array_data(i)
  File "/home/karimimonsefi.1/miniconda3/lib/python3.9/site-packages/monai/data/image_reader.py", line 522, in _get_array_data
    _array = np.array(img.get_fdata(dtype=self.dtype))
  File "/home/karimimonsefi.1/miniconda3/lib/python3.9/site-packages/nibabel/dataobj_images.py", line 368, in get_fdata
    data = np.asanyarray(self._dataobj, dtype=dtype)
  File "/home/karimimonsefi.1/miniconda3/lib/python3.9/site-packages/nibabel/arrayproxy.py", line 426, in __array__
    arr = self._get_scaled(dtype=dtype, slicer=())
  File "/home/karimimonsefi.1/miniconda3/lib/python3.9/site-packages/nibabel/arrayproxy.py", line 393, in _get_scaled
    scaled = apply_read_scaling(self._get_unscaled(slicer=slicer), scl_slope, scl_inter)
  File "/home/karimimonsefi.1/miniconda3/lib/python3.9/site-packages/nibabel/arrayproxy.py", line 363, in _get_unscaled
    return array_from_file(
  File "/home/karimimonsefi.1/miniconda3/lib/python3.9/site-packages/nibabel/volumeutils.py", line 454, in array_from_file
    n_read = infile.readinto(data_bytes)
  File "/home/karimimonsefi.1/miniconda3/lib/python3.9/gzip.py", line 300, in read
    return self._buffer.read(size)
  File "/home/karimimonsefi.1/miniconda3/lib/python3.9/_compression.py", line 68, in readinto
    data = self.read(len(byte_view))
  File "/home/karimimonsefi.1/miniconda3/lib/python3.9/gzip.py", line 506, in read
    raise EOFError("Compressed file ended before the "
EOFError: Compressed file ended before the end-of-stream marker was reached

The above exception was the direct cause of the following exception:

Traceback (most recent call last):
  File "/home/karimimonsefi.1/miniconda3/lib/python3.9/site-packages/monai/transforms/transform.py", line 89, in apply_transform
    return _apply_transform(transform, data, unpack_items)
  File "/home/karimimonsefi.1/miniconda3/lib/python3.9/site-packages/monai/transforms/transform.py", line 53, in _apply_transform
    return transform(parameters)
  File "/home/karimimonsefi.1/miniconda3/lib/python3.9/site-packages/monai/transforms/compose.py", line 173, in __call__
    input_ = apply_transform(_transform, input_, self.map_items, self.unpack_items, self.log_stats)
  File "/home/karimimonsefi.1/miniconda3/lib/python3.9/site-packages/monai/transforms/transform.py", line 113, in apply_transform
    raise RuntimeError(f"applying transform {transform}") from e
RuntimeError: applying transform <monai.transforms.io.dictionary.LoadImaged object at 0x1496ea59cbe0>

The above exception was the direct cause of the following exception:

Traceback (most recent call last):
  File "/home/karimimonsefi.1/miniconda3/lib/python3.9/site-packages/torch/utils/data/_utils/worker.py", line 302, in _worker_loop
    data = fetcher.fetch(index)
  File "/home/karimimonsefi.1/miniconda3/lib/python3.9/site-packages/torch/utils/data/_utils/fetch.py", line 58, in fetch
    data = [self.dataset[idx] for idx in possibly_batched_index]
  File "/home/karimimonsefi.1/miniconda3/lib/python3.9/site-packages/torch/utils/data/_utils/fetch.py", line 58, in <listcomp>
    data = [self.dataset[idx] for idx in possibly_batched_index]
  File "/home/karimimonsefi.1/miniconda3/lib/python3.9/site-packages/monai/data/dataset.py", line 97, in __getitem__
    return self._transform(index)
  File "/home/karimimonsefi.1/miniconda3/lib/python3.9/site-packages/monai/data/dataset.py", line 83, in _transform
    return apply_transform(self.transform, data_i) if self.transform is not None else data_i
  File "/home/karimimonsefi.1/miniconda3/lib/python3.9/site-packages/monai/transforms/transform.py", line 113, in apply_transform
    raise RuntimeError(f"applying transform {transform}") from e
RuntimeError: applying transform <monai.transforms.compose.Compose object at 0x1495d67c1640>

2023-04-28 11:07:49 | INFO | root | Namespace(a_min=-1000, a_max=1000, b_min=0.0, b_max=1.0, space_x=1.5, space_y=1.5, space_z=2.0, roi_x=96, roi_y=96, roi_z=96, num_workers=32, distributed=False, mode='server', num_samples=6, km_path='./cluster_models_1/cluster_model_1_{}_{}_{}.joblib', n_clusters=131, seed=42, init='k-means++', max_iter=250, batch_size=20, tol=0.0, max_no_improvement=100, n_init=50, reassignment_ratio=0.0)
Dataset 1 LUNA16: number of data: 842
Dataset 2 Covid 19: OK number of data: 722
Dataset 3 HNSCC: number of data: 954
Dataset 4 TCIA Colon: number of data: 1535
Dataset 5 TCIA LIDC: OK number of data: 450
Dataset all training: number of data: 1535
loader is ready
2023-04-28 11:08:49 | INFO | learn_kmeans | for batch number 0 the res size is 0
2023-04-28 11:12:38 | INFO | learn_kmeans | for batch number 1 the res size is 2304
2023-04-28 11:12:41 | INFO | learn_kmeans | for batch number 2 the res size is 3456
2023-04-28 11:15:18 | INFO | learn_kmeans | for batch number 3 the res size is 4608
2023-04-28 11:17:17 | INFO | learn_kmeans | for batch number 4 the res size is 5760
2023-04-28 11:17:17 | INFO | learn_kmeans | for batch number 5 the res size is 6912
2023-04-28 11:17:18 | INFO | learn_kmeans | for batch number 6 the res size is 8064
2023-04-28 11:17:18 | INFO | learn_kmeans | for batch number 7 the res size is 9216
2023-04-28 11:17:18 | INFO | learn_kmeans | for batch number 8 the res size is 10368
2023-04-28 11:17:18 | INFO | learn_kmeans | for batch number 9 the res size is 11520
2023-04-28 11:17:18 | INFO | learn_kmeans | for batch number 10 the res size is 12672
2023-04-28 11:17:18 | INFO | learn_kmeans | for batch number 11 the res size is 13824
2023-04-28 11:17:18 | INFO | learn_kmeans | for batch number 12 the res size is 14976
2023-04-28 11:17:18 | INFO | learn_kmeans | for batch number 13 the res size is 16128
2023-04-28 11:17:18 | INFO | learn_kmeans | for batch number 14 the res size is 17280
2023-04-28 11:17:18 | INFO | learn_kmeans | for batch number 15 the res size is 18432
2023-04-28 11:17:18 | INFO | learn_kmeans | for batch number 16 the res size is 19584
2023-04-28 11:17:18 | INFO | learn_kmeans | for batch number 17 the res size is 20736
2023-04-28 11:17:18 | INFO | learn_kmeans | for batch number 18 the res size is 21888
2023-04-28 11:17:18 | INFO | learn_kmeans | for batch number 19 the res size is 23040
2023-04-28 11:17:18 | INFO | learn_kmeans | for batch number 20 the res size is 24192
2023-04-28 11:17:18 | INFO | learn_kmeans | for batch number 21 the res size is 25344
Traceback (most recent call last):
  File "/home/karimimonsefi.1/SSL_VAN/clustering/kmeans_learning.py", line 145, in <module>
    learn_kmeans(args)
  File "/home/karimimonsefi.1/SSL_VAN/clustering/kmeans_learning.py", line 73, in learn_kmeans
    feat = load_data(args)
  File "/home/karimimonsefi.1/SSL_VAN/clustering/kmeans_learning.py", line 50, in load_data
    for idx, batch_data in enumerate(training_loader):
  File "/home/karimimonsefi.1/miniconda3/lib/python3.9/site-packages/torch/utils/data/dataloader.py", line 628, in __next__
    data = self._next_data()
  File "/home/karimimonsefi.1/miniconda3/lib/python3.9/site-packages/torch/utils/data/dataloader.py", line 1313, in _next_data
    return self._process_data(data)
  File "/home/karimimonsefi.1/miniconda3/lib/python3.9/site-packages/torch/utils/data/dataloader.py", line 1359, in _process_data
    data.reraise()
  File "/home/karimimonsefi.1/miniconda3/lib/python3.9/site-packages/torch/_utils.py", line 543, in reraise
    raise exception
RuntimeError: Caught RuntimeError in DataLoader worker process 22.
Original Traceback (most recent call last):
  File "/home/karimimonsefi.1/miniconda3/lib/python3.9/site-packages/monai/transforms/transform.py", line 89, in apply_transform
    return _apply_transform(transform, data, unpack_items)
  File "/home/karimimonsefi.1/miniconda3/lib/python3.9/site-packages/monai/transforms/transform.py", line 53, in _apply_transform
    return transform(parameters)
  File "/home/karimimonsefi.1/miniconda3/lib/python3.9/site-packages/monai/transforms/io/dictionary.py", line 131, in __call__
    data = self._loader(d[key], reader)
  File "/home/karimimonsefi.1/miniconda3/lib/python3.9/site-packages/monai/transforms/io/array.py", line 240, in __call__
    img_array, meta_data = reader.get_data(img)
  File "/home/karimimonsefi.1/miniconda3/lib/python3.9/site-packages/monai/data/image_reader.py", line 450, in get_data
    data = self._get_array_data(i)
  File "/home/karimimonsefi.1/miniconda3/lib/python3.9/site-packages/monai/data/image_reader.py", line 522, in _get_array_data
    _array = np.array(img.get_fdata(dtype=self.dtype))
  File "/home/karimimonsefi.1/miniconda3/lib/python3.9/site-packages/nibabel/dataobj_images.py", line 368, in get_fdata
    data = np.asanyarray(self._dataobj, dtype=dtype)
  File "/home/karimimonsefi.1/miniconda3/lib/python3.9/site-packages/nibabel/arrayproxy.py", line 426, in __array__
    arr = self._get_scaled(dtype=dtype, slicer=())
  File "/home/karimimonsefi.1/miniconda3/lib/python3.9/site-packages/nibabel/arrayproxy.py", line 393, in _get_scaled
    scaled = apply_read_scaling(self._get_unscaled(slicer=slicer), scl_slope, scl_inter)
  File "/home/karimimonsefi.1/miniconda3/lib/python3.9/site-packages/nibabel/arrayproxy.py", line 363, in _get_unscaled
    return array_from_file(
  File "/home/karimimonsefi.1/miniconda3/lib/python3.9/site-packages/nibabel/volumeutils.py", line 454, in array_from_file
    n_read = infile.readinto(data_bytes)
  File "/home/karimimonsefi.1/miniconda3/lib/python3.9/gzip.py", line 300, in read
    return self._buffer.read(size)
  File "/home/karimimonsefi.1/miniconda3/lib/python3.9/_compression.py", line 68, in readinto
    data = self.read(len(byte_view))
  File "/home/karimimonsefi.1/miniconda3/lib/python3.9/gzip.py", line 506, in read
    raise EOFError("Compressed file ended before the "
EOFError: Compressed file ended before the end-of-stream marker was reached

The above exception was the direct cause of the following exception:

Traceback (most recent call last):
  File "/home/karimimonsefi.1/miniconda3/lib/python3.9/site-packages/monai/transforms/transform.py", line 89, in apply_transform
    return _apply_transform(transform, data, unpack_items)
  File "/home/karimimonsefi.1/miniconda3/lib/python3.9/site-packages/monai/transforms/transform.py", line 53, in _apply_transform
    return transform(parameters)
  File "/home/karimimonsefi.1/miniconda3/lib/python3.9/site-packages/monai/transforms/compose.py", line 173, in __call__
    input_ = apply_transform(_transform, input_, self.map_items, self.unpack_items, self.log_stats)
  File "/home/karimimonsefi.1/miniconda3/lib/python3.9/site-packages/monai/transforms/transform.py", line 113, in apply_transform
    raise RuntimeError(f"applying transform {transform}") from e
RuntimeError: applying transform <monai.transforms.io.dictionary.LoadImaged object at 0x14a097d13be0>

The above exception was the direct cause of the following exception:

Traceback (most recent call last):
  File "/home/karimimonsefi.1/miniconda3/lib/python3.9/site-packages/torch/utils/data/_utils/worker.py", line 302, in _worker_loop
    data = fetcher.fetch(index)
  File "/home/karimimonsefi.1/miniconda3/lib/python3.9/site-packages/torch/utils/data/_utils/fetch.py", line 58, in fetch
    data = [self.dataset[idx] for idx in possibly_batched_index]
  File "/home/karimimonsefi.1/miniconda3/lib/python3.9/site-packages/torch/utils/data/_utils/fetch.py", line 58, in <listcomp>
    data = [self.dataset[idx] for idx in possibly_batched_index]
  File "/home/karimimonsefi.1/miniconda3/lib/python3.9/site-packages/monai/data/dataset.py", line 97, in __getitem__
    return self._transform(index)
  File "/home/karimimonsefi.1/miniconda3/lib/python3.9/site-packages/monai/data/dataset.py", line 83, in _transform
    return apply_transform(self.transform, data_i) if self.transform is not None else data_i
  File "/home/karimimonsefi.1/miniconda3/lib/python3.9/site-packages/monai/transforms/transform.py", line 113, in apply_transform
    raise RuntimeError(f"applying transform {transform}") from e
RuntimeError: applying transform <monai.transforms.compose.Compose object at 0x149f83f37640>

2023-04-28 11:17:53 | INFO | root | Namespace(a_min=-1000, a_max=1000, b_min=0.0, b_max=1.0, space_x=1.5, space_y=1.5, space_z=2.0, roi_x=96, roi_y=96, roi_z=96, num_workers=32, distributed=False, mode='server', num_samples=6, km_path='./cluster_models_1/cluster_model_1_{}_{}_{}.joblib', n_clusters=110, seed=42, init='k-means++', max_iter=250, batch_size=20, tol=0.0, max_no_improvement=100, n_init=50, reassignment_ratio=0.0)
Dataset 1 LUNA16: number of data: 842
Dataset 2 Covid 19: OK number of data: 722
Dataset 3 HNSCC: number of data: 954
Dataset 4 TCIA Colon: number of data: 1535
Dataset 5 TCIA LIDC: OK number of data: 450
Dataset all training: number of data: 1535
loader is ready
2023-04-28 11:25:22 | INFO | learn_kmeans | for batch number 0 the res size is 0
2023-04-28 11:26:59 | INFO | learn_kmeans | for batch number 1 the res size is 2304
2023-04-28 11:27:00 | INFO | learn_kmeans | for batch number 2 the res size is 3456
2023-04-28 11:27:00 | INFO | learn_kmeans | for batch number 3 the res size is 4608
2023-04-28 11:27:00 | INFO | learn_kmeans | for batch number 4 the res size is 5760
2023-04-28 11:27:00 | INFO | learn_kmeans | for batch number 5 the res size is 6912
2023-04-28 11:27:00 | INFO | learn_kmeans | for batch number 6 the res size is 8064
2023-04-28 11:27:00 | INFO | learn_kmeans | for batch number 7 the res size is 9216
2023-04-28 11:27:00 | INFO | learn_kmeans | for batch number 8 the res size is 10368
2023-04-28 11:27:00 | INFO | learn_kmeans | for batch number 9 the res size is 11520
2023-04-28 11:27:00 | INFO | learn_kmeans | for batch number 10 the res size is 12672
2023-04-28 11:27:00 | INFO | learn_kmeans | for batch number 11 the res size is 13824
2023-04-28 11:27:01 | INFO | learn_kmeans | for batch number 12 the res size is 14976
2023-04-28 11:27:01 | INFO | learn_kmeans | for batch number 13 the res size is 16128
2023-04-28 11:27:01 | INFO | learn_kmeans | for batch number 14 the res size is 17280
2023-04-28 11:27:01 | INFO | learn_kmeans | for batch number 15 the res size is 18432
2023-04-28 11:27:01 | INFO | learn_kmeans | for batch number 16 the res size is 19584
2023-04-28 11:27:34 | INFO | learn_kmeans | for batch number 17 the res size is 20736
2023-04-28 11:27:35 | INFO | learn_kmeans | for batch number 18 the res size is 21888
2023-04-28 11:27:35 | INFO | learn_kmeans | for batch number 19 the res size is 23040
2023-04-28 11:27:35 | INFO | learn_kmeans | for batch number 20 the res size is 24192
2023-04-28 11:27:35 | INFO | learn_kmeans | for batch number 21 the res size is 25344
Traceback (most recent call last):
  File "/home/karimimonsefi.1/SSL_VAN/clustering/kmeans_learning.py", line 145, in <module>
    learn_kmeans(args)
  File "/home/karimimonsefi.1/SSL_VAN/clustering/kmeans_learning.py", line 73, in learn_kmeans
    feat = load_data(args)
  File "/home/karimimonsefi.1/SSL_VAN/clustering/kmeans_learning.py", line 50, in load_data
    for idx, batch_data in enumerate(training_loader):
  File "/home/karimimonsefi.1/miniconda3/lib/python3.9/site-packages/torch/utils/data/dataloader.py", line 628, in __next__
    data = self._next_data()
  File "/home/karimimonsefi.1/miniconda3/lib/python3.9/site-packages/torch/utils/data/dataloader.py", line 1313, in _next_data
    return self._process_data(data)
  File "/home/karimimonsefi.1/miniconda3/lib/python3.9/site-packages/torch/utils/data/dataloader.py", line 1359, in _process_data
    data.reraise()
  File "/home/karimimonsefi.1/miniconda3/lib/python3.9/site-packages/torch/_utils.py", line 543, in reraise
    raise exception
RuntimeError: Caught RuntimeError in DataLoader worker process 22.
Original Traceback (most recent call last):
  File "/home/karimimonsefi.1/miniconda3/lib/python3.9/site-packages/monai/transforms/transform.py", line 89, in apply_transform
    return _apply_transform(transform, data, unpack_items)
  File "/home/karimimonsefi.1/miniconda3/lib/python3.9/site-packages/monai/transforms/transform.py", line 53, in _apply_transform
    return transform(parameters)
  File "/home/karimimonsefi.1/miniconda3/lib/python3.9/site-packages/monai/transforms/io/dictionary.py", line 131, in __call__
    data = self._loader(d[key], reader)
  File "/home/karimimonsefi.1/miniconda3/lib/python3.9/site-packages/monai/transforms/io/array.py", line 240, in __call__
    img_array, meta_data = reader.get_data(img)
  File "/home/karimimonsefi.1/miniconda3/lib/python3.9/site-packages/monai/data/image_reader.py", line 450, in get_data
    data = self._get_array_data(i)
  File "/home/karimimonsefi.1/miniconda3/lib/python3.9/site-packages/monai/data/image_reader.py", line 522, in _get_array_data
    _array = np.array(img.get_fdata(dtype=self.dtype))
  File "/home/karimimonsefi.1/miniconda3/lib/python3.9/site-packages/nibabel/dataobj_images.py", line 368, in get_fdata
    data = np.asanyarray(self._dataobj, dtype=dtype)
  File "/home/karimimonsefi.1/miniconda3/lib/python3.9/site-packages/nibabel/arrayproxy.py", line 426, in __array__
    arr = self._get_scaled(dtype=dtype, slicer=())
  File "/home/karimimonsefi.1/miniconda3/lib/python3.9/site-packages/nibabel/arrayproxy.py", line 393, in _get_scaled
    scaled = apply_read_scaling(self._get_unscaled(slicer=slicer), scl_slope, scl_inter)
  File "/home/karimimonsefi.1/miniconda3/lib/python3.9/site-packages/nibabel/arrayproxy.py", line 363, in _get_unscaled
    return array_from_file(
  File "/home/karimimonsefi.1/miniconda3/lib/python3.9/site-packages/nibabel/volumeutils.py", line 454, in array_from_file
    n_read = infile.readinto(data_bytes)
  File "/home/karimimonsefi.1/miniconda3/lib/python3.9/gzip.py", line 300, in read
    return self._buffer.read(size)
  File "/home/karimimonsefi.1/miniconda3/lib/python3.9/_compression.py", line 68, in readinto
    data = self.read(len(byte_view))
  File "/home/karimimonsefi.1/miniconda3/lib/python3.9/gzip.py", line 506, in read
    raise EOFError("Compressed file ended before the "
EOFError: Compressed file ended before the end-of-stream marker was reached

The above exception was the direct cause of the following exception:

Traceback (most recent call last):
  File "/home/karimimonsefi.1/miniconda3/lib/python3.9/site-packages/monai/transforms/transform.py", line 89, in apply_transform
    return _apply_transform(transform, data, unpack_items)
  File "/home/karimimonsefi.1/miniconda3/lib/python3.9/site-packages/monai/transforms/transform.py", line 53, in _apply_transform
    return transform(parameters)
  File "/home/karimimonsefi.1/miniconda3/lib/python3.9/site-packages/monai/transforms/compose.py", line 173, in __call__
    input_ = apply_transform(_transform, input_, self.map_items, self.unpack_items, self.log_stats)
  File "/home/karimimonsefi.1/miniconda3/lib/python3.9/site-packages/monai/transforms/transform.py", line 113, in apply_transform
    raise RuntimeError(f"applying transform {transform}") from e
RuntimeError: applying transform <monai.transforms.io.dictionary.LoadImaged object at 0x14773d9fdbe0>

The above exception was the direct cause of the following exception:

Traceback (most recent call last):
  File "/home/karimimonsefi.1/miniconda3/lib/python3.9/site-packages/torch/utils/data/_utils/worker.py", line 302, in _worker_loop
    data = fetcher.fetch(index)
  File "/home/karimimonsefi.1/miniconda3/lib/python3.9/site-packages/torch/utils/data/_utils/fetch.py", line 58, in fetch
    data = [self.dataset[idx] for idx in possibly_batched_index]
  File "/home/karimimonsefi.1/miniconda3/lib/python3.9/site-packages/torch/utils/data/_utils/fetch.py", line 58, in <listcomp>
    data = [self.dataset[idx] for idx in possibly_batched_index]
  File "/home/karimimonsefi.1/miniconda3/lib/python3.9/site-packages/monai/data/dataset.py", line 97, in __getitem__
    return self._transform(index)
  File "/home/karimimonsefi.1/miniconda3/lib/python3.9/site-packages/monai/data/dataset.py", line 83, in _transform
    return apply_transform(self.transform, data_i) if self.transform is not None else data_i
  File "/home/karimimonsefi.1/miniconda3/lib/python3.9/site-packages/monai/transforms/transform.py", line 113, in apply_transform
    raise RuntimeError(f"applying transform {transform}") from e
RuntimeError: applying transform <monai.transforms.compose.Compose object at 0x147629c22610>

2023-04-28 11:27:58 | INFO | root | Namespace(a_min=-1000, a_max=1000, b_min=0.0, b_max=1.0, space_x=1.5, space_y=1.5, space_z=2.0, roi_x=96, roi_y=96, roi_z=96, num_workers=32, distributed=False, mode='server', num_samples=6, km_path='./cluster_models_1/cluster_model_1_{}_{}_{}.joblib', n_clusters=124, seed=42, init='k-means++', max_iter=250, batch_size=20, tol=0.0, max_no_improvement=100, n_init=50, reassignment_ratio=0.0)
Dataset 1 LUNA16: number of data: 842
Dataset 2 Covid 19: OK number of data: 722
Dataset 3 HNSCC: number of data: 954
Dataset 4 TCIA Colon: number of data: 1535
Dataset 5 TCIA LIDC: OK number of data: 450
Dataset all training: number of data: 1535
loader is ready
2023-04-28 11:31:36 | INFO | learn_kmeans | for batch number 0 the res size is 0
2023-04-28 11:31:37 | INFO | learn_kmeans | for batch number 1 the res size is 2304
2023-04-28 11:37:24 | INFO | learn_kmeans | for batch number 2 the res size is 3456
2023-04-28 11:37:24 | INFO | learn_kmeans | for batch number 3 the res size is 4608
2023-04-28 11:37:24 | INFO | learn_kmeans | for batch number 4 the res size is 5760
2023-04-28 11:37:24 | INFO | learn_kmeans | for batch number 5 the res size is 6912
2023-04-28 11:37:25 | INFO | learn_kmeans | for batch number 6 the res size is 8064
2023-04-28 11:37:50 | INFO | learn_kmeans | for batch number 7 the res size is 9216
2023-04-28 11:37:50 | INFO | learn_kmeans | for batch number 8 the res size is 10368
2023-04-28 11:37:50 | INFO | learn_kmeans | for batch number 9 the res size is 11520
2023-04-28 11:37:50 | INFO | learn_kmeans | for batch number 10 the res size is 12672
2023-04-28 11:37:50 | INFO | learn_kmeans | for batch number 11 the res size is 13824
2023-04-28 11:37:50 | INFO | learn_kmeans | for batch number 12 the res size is 14976
2023-04-28 11:37:50 | INFO | learn_kmeans | for batch number 13 the res size is 16128
2023-04-28 11:37:50 | INFO | learn_kmeans | for batch number 14 the res size is 17280
2023-04-28 11:37:51 | INFO | learn_kmeans | for batch number 15 the res size is 18432
2023-04-28 11:37:51 | INFO | learn_kmeans | for batch number 16 the res size is 19584
2023-04-28 11:37:51 | INFO | learn_kmeans | for batch number 17 the res size is 20736
2023-04-28 11:37:51 | INFO | learn_kmeans | for batch number 18 the res size is 21888
2023-04-28 11:37:51 | INFO | learn_kmeans | for batch number 19 the res size is 23040
Traceback (most recent call last):
  File "/home/karimimonsefi.1/SSL_VAN/clustering/kmeans_learning.py", line 145, in <module>
    learn_kmeans(args)
  File "/home/karimimonsefi.1/SSL_VAN/clustering/kmeans_learning.py", line 73, in learn_kmeans
    feat = load_data(args)
  File "/home/karimimonsefi.1/SSL_VAN/clustering/kmeans_learning.py", line 50, in load_data
    for idx, batch_data in enumerate(training_loader):
  File "/home/karimimonsefi.1/miniconda3/lib/python3.9/site-packages/torch/utils/data/dataloader.py", line 628, in __next__
    data = self._next_data()
  File "/home/karimimonsefi.1/miniconda3/lib/python3.9/site-packages/torch/utils/data/dataloader.py", line 1313, in _next_data
    return self._process_data(data)
  File "/home/karimimonsefi.1/miniconda3/lib/python3.9/site-packages/torch/utils/data/dataloader.py", line 1359, in _process_data
    data.reraise()
  File "/home/karimimonsefi.1/miniconda3/lib/python3.9/site-packages/torch/_utils.py", line 543, in reraise
    raise exception
RuntimeError: Caught RuntimeError in DataLoader worker process 20.
Original Traceback (most recent call last):
  File "/home/karimimonsefi.1/miniconda3/lib/python3.9/site-packages/monai/transforms/transform.py", line 89, in apply_transform
    return _apply_transform(transform, data, unpack_items)
  File "/home/karimimonsefi.1/miniconda3/lib/python3.9/site-packages/monai/transforms/transform.py", line 53, in _apply_transform
    return transform(parameters)
  File "/home/karimimonsefi.1/miniconda3/lib/python3.9/site-packages/monai/transforms/io/dictionary.py", line 131, in __call__
    data = self._loader(d[key], reader)
  File "/home/karimimonsefi.1/miniconda3/lib/python3.9/site-packages/monai/transforms/io/array.py", line 240, in __call__
    img_array, meta_data = reader.get_data(img)
  File "/home/karimimonsefi.1/miniconda3/lib/python3.9/site-packages/monai/data/image_reader.py", line 450, in get_data
    data = self._get_array_data(i)
  File "/home/karimimonsefi.1/miniconda3/lib/python3.9/site-packages/monai/data/image_reader.py", line 522, in _get_array_data
    _array = np.array(img.get_fdata(dtype=self.dtype))
  File "/home/karimimonsefi.1/miniconda3/lib/python3.9/site-packages/nibabel/dataobj_images.py", line 368, in get_fdata
    data = np.asanyarray(self._dataobj, dtype=dtype)
  File "/home/karimimonsefi.1/miniconda3/lib/python3.9/site-packages/nibabel/arrayproxy.py", line 426, in __array__
    arr = self._get_scaled(dtype=dtype, slicer=())
  File "/home/karimimonsefi.1/miniconda3/lib/python3.9/site-packages/nibabel/arrayproxy.py", line 393, in _get_scaled
    scaled = apply_read_scaling(self._get_unscaled(slicer=slicer), scl_slope, scl_inter)
  File "/home/karimimonsefi.1/miniconda3/lib/python3.9/site-packages/nibabel/arrayproxy.py", line 363, in _get_unscaled
    return array_from_file(
  File "/home/karimimonsefi.1/miniconda3/lib/python3.9/site-packages/nibabel/volumeutils.py", line 454, in array_from_file
    n_read = infile.readinto(data_bytes)
  File "/home/karimimonsefi.1/miniconda3/lib/python3.9/gzip.py", line 300, in read
    return self._buffer.read(size)
  File "/home/karimimonsefi.1/miniconda3/lib/python3.9/_compression.py", line 68, in readinto
    data = self.read(len(byte_view))
  File "/home/karimimonsefi.1/miniconda3/lib/python3.9/gzip.py", line 506, in read
    raise EOFError("Compressed file ended before the "
EOFError: Compressed file ended before the end-of-stream marker was reached

The above exception was the direct cause of the following exception:

Traceback (most recent call last):
  File "/home/karimimonsefi.1/miniconda3/lib/python3.9/site-packages/monai/transforms/transform.py", line 89, in apply_transform
    return _apply_transform(transform, data, unpack_items)
  File "/home/karimimonsefi.1/miniconda3/lib/python3.9/site-packages/monai/transforms/transform.py", line 53, in _apply_transform
    return transform(parameters)
  File "/home/karimimonsefi.1/miniconda3/lib/python3.9/site-packages/monai/transforms/compose.py", line 173, in __call__
    input_ = apply_transform(_transform, input_, self.map_items, self.unpack_items, self.log_stats)
  File "/home/karimimonsefi.1/miniconda3/lib/python3.9/site-packages/monai/transforms/transform.py", line 113, in apply_transform
    raise RuntimeError(f"applying transform {transform}") from e
RuntimeError: applying transform <monai.transforms.io.dictionary.LoadImaged object at 0x14cd76d99be0>

The above exception was the direct cause of the following exception:

Traceback (most recent call last):
  File "/home/karimimonsefi.1/miniconda3/lib/python3.9/site-packages/torch/utils/data/_utils/worker.py", line 302, in _worker_loop
    data = fetcher.fetch(index)
  File "/home/karimimonsefi.1/miniconda3/lib/python3.9/site-packages/torch/utils/data/_utils/fetch.py", line 58, in fetch
    data = [self.dataset[idx] for idx in possibly_batched_index]
  File "/home/karimimonsefi.1/miniconda3/lib/python3.9/site-packages/torch/utils/data/_utils/fetch.py", line 58, in <listcomp>
    data = [self.dataset[idx] for idx in possibly_batched_index]
  File "/home/karimimonsefi.1/miniconda3/lib/python3.9/site-packages/monai/data/dataset.py", line 97, in __getitem__
    return self._transform(index)
  File "/home/karimimonsefi.1/miniconda3/lib/python3.9/site-packages/monai/data/dataset.py", line 83, in _transform
    return apply_transform(self.transform, data_i) if self.transform is not None else data_i
  File "/home/karimimonsefi.1/miniconda3/lib/python3.9/site-packages/monai/transforms/transform.py", line 113, in apply_transform
    raise RuntimeError(f"applying transform {transform}") from e
RuntimeError: applying transform <monai.transforms.compose.Compose object at 0x14cc62fbee80>

2023-04-28 11:38:26 | INFO | root | Namespace(a_min=-1000, a_max=1000, b_min=0.0, b_max=1.0, space_x=1.5, space_y=1.5, space_z=2.0, roi_x=96, roi_y=96, roi_z=96, num_workers=32, distributed=False, mode='server', num_samples=6, km_path='./cluster_models_1/cluster_model_1_{}_{}_{}.joblib', n_clusters=456, seed=42, init='k-means++', max_iter=250, batch_size=20, tol=0.0, max_no_improvement=100, n_init=50, reassignment_ratio=0.0)
Dataset 1 LUNA16: number of data: 842
Dataset 2 Covid 19: OK number of data: 722
Dataset 3 HNSCC: number of data: 954
Dataset 4 TCIA Colon: number of data: 1535
Dataset 5 TCIA LIDC: OK number of data: 450
Dataset all training: number of data: 1535
loader is ready
2023-04-28 11:47:17 | INFO | learn_kmeans | for batch number 0 the res size is 0
2023-04-28 11:47:20 | INFO | learn_kmeans | for batch number 1 the res size is 2304
2023-04-28 11:47:21 | INFO | learn_kmeans | for batch number 2 the res size is 3456
2023-04-28 11:47:21 | INFO | learn_kmeans | for batch number 3 the res size is 4608
Traceback (most recent call last):
  File "/home/karimimonsefi.1/SSL_VAN/clustering/kmeans_learning.py", line 145, in <module>
    learn_kmeans(args)
  File "/home/karimimonsefi.1/SSL_VAN/clustering/kmeans_learning.py", line 73, in learn_kmeans
    feat = load_data(args)
  File "/home/karimimonsefi.1/SSL_VAN/clustering/kmeans_learning.py", line 50, in load_data
    for idx, batch_data in enumerate(training_loader):
  File "/home/karimimonsefi.1/miniconda3/lib/python3.9/site-packages/torch/utils/data/dataloader.py", line 628, in __next__
    data = self._next_data()
  File "/home/karimimonsefi.1/miniconda3/lib/python3.9/site-packages/torch/utils/data/dataloader.py", line 1313, in _next_data
    return self._process_data(data)
  File "/home/karimimonsefi.1/miniconda3/lib/python3.9/site-packages/torch/utils/data/dataloader.py", line 1359, in _process_data
    data.reraise()
  File "/home/karimimonsefi.1/miniconda3/lib/python3.9/site-packages/torch/_utils.py", line 543, in reraise
    raise exception
RuntimeError: Caught RuntimeError in DataLoader worker process 4.
Original Traceback (most recent call last):
  File "/home/karimimonsefi.1/miniconda3/lib/python3.9/site-packages/monai/transforms/transform.py", line 89, in apply_transform
    return _apply_transform(transform, data, unpack_items)
  File "/home/karimimonsefi.1/miniconda3/lib/python3.9/site-packages/monai/transforms/transform.py", line 53, in _apply_transform
    return transform(parameters)
  File "/home/karimimonsefi.1/miniconda3/lib/python3.9/site-packages/monai/transforms/io/dictionary.py", line 131, in __call__
    data = self._loader(d[key], reader)
  File "/home/karimimonsefi.1/miniconda3/lib/python3.9/site-packages/monai/transforms/io/array.py", line 240, in __call__
    img_array, meta_data = reader.get_data(img)
  File "/home/karimimonsefi.1/miniconda3/lib/python3.9/site-packages/monai/data/image_reader.py", line 450, in get_data
    data = self._get_array_data(i)
  File "/home/karimimonsefi.1/miniconda3/lib/python3.9/site-packages/monai/data/image_reader.py", line 522, in _get_array_data
    _array = np.array(img.get_fdata(dtype=self.dtype))
  File "/home/karimimonsefi.1/miniconda3/lib/python3.9/site-packages/nibabel/dataobj_images.py", line 368, in get_fdata
    data = np.asanyarray(self._dataobj, dtype=dtype)
  File "/home/karimimonsefi.1/miniconda3/lib/python3.9/site-packages/nibabel/arrayproxy.py", line 426, in __array__
    arr = self._get_scaled(dtype=dtype, slicer=())
  File "/home/karimimonsefi.1/miniconda3/lib/python3.9/site-packages/nibabel/arrayproxy.py", line 393, in _get_scaled
    scaled = apply_read_scaling(self._get_unscaled(slicer=slicer), scl_slope, scl_inter)
  File "/home/karimimonsefi.1/miniconda3/lib/python3.9/site-packages/nibabel/arrayproxy.py", line 363, in _get_unscaled
    return array_from_file(
  File "/home/karimimonsefi.1/miniconda3/lib/python3.9/site-packages/nibabel/volumeutils.py", line 454, in array_from_file
    n_read = infile.readinto(data_bytes)
  File "/home/karimimonsefi.1/miniconda3/lib/python3.9/gzip.py", line 300, in read
    return self._buffer.read(size)
  File "/home/karimimonsefi.1/miniconda3/lib/python3.9/_compression.py", line 68, in readinto
    data = self.read(len(byte_view))
  File "/home/karimimonsefi.1/miniconda3/lib/python3.9/gzip.py", line 495, in read
    uncompress = self._decompressor.decompress(buf, size)
zlib.error: Error -3 while decompressing data: invalid block type

The above exception was the direct cause of the following exception:

Traceback (most recent call last):
  File "/home/karimimonsefi.1/miniconda3/lib/python3.9/site-packages/monai/transforms/transform.py", line 89, in apply_transform
    return _apply_transform(transform, data, unpack_items)
  File "/home/karimimonsefi.1/miniconda3/lib/python3.9/site-packages/monai/transforms/transform.py", line 53, in _apply_transform
    return transform(parameters)
  File "/home/karimimonsefi.1/miniconda3/lib/python3.9/site-packages/monai/transforms/compose.py", line 173, in __call__
    input_ = apply_transform(_transform, input_, self.map_items, self.unpack_items, self.log_stats)
  File "/home/karimimonsefi.1/miniconda3/lib/python3.9/site-packages/monai/transforms/transform.py", line 113, in apply_transform
    raise RuntimeError(f"applying transform {transform}") from e
RuntimeError: applying transform <monai.transforms.io.dictionary.LoadImaged object at 0x150f52ca2be0>

The above exception was the direct cause of the following exception:

Traceback (most recent call last):
  File "/home/karimimonsefi.1/miniconda3/lib/python3.9/site-packages/torch/utils/data/_utils/worker.py", line 302, in _worker_loop
    data = fetcher.fetch(index)
  File "/home/karimimonsefi.1/miniconda3/lib/python3.9/site-packages/torch/utils/data/_utils/fetch.py", line 58, in fetch
    data = [self.dataset[idx] for idx in possibly_batched_index]
  File "/home/karimimonsefi.1/miniconda3/lib/python3.9/site-packages/torch/utils/data/_utils/fetch.py", line 58, in <listcomp>
    data = [self.dataset[idx] for idx in possibly_batched_index]
  File "/home/karimimonsefi.1/miniconda3/lib/python3.9/site-packages/monai/data/dataset.py", line 97, in __getitem__
    return self._transform(index)
  File "/home/karimimonsefi.1/miniconda3/lib/python3.9/site-packages/monai/data/dataset.py", line 83, in _transform
    return apply_transform(self.transform, data_i) if self.transform is not None else data_i
  File "/home/karimimonsefi.1/miniconda3/lib/python3.9/site-packages/monai/transforms/transform.py", line 113, in apply_transform
    raise RuntimeError(f"applying transform {transform}") from e
RuntimeError: applying transform <monai.transforms.compose.Compose object at 0x150e3eec7610>

2023-04-28 11:47:43 | INFO | root | Namespace(a_min=-1000, a_max=1000, b_min=0.0, b_max=1.0, space_x=1.5, space_y=1.5, space_z=2.0, roi_x=96, roi_y=96, roi_z=96, num_workers=32, distributed=False, mode='server', num_samples=6, km_path='./cluster_models_1/cluster_model_1_{}_{}_{}.joblib', n_clusters=253, seed=42, init='k-means++', max_iter=250, batch_size=20, tol=0.0, max_no_improvement=100, n_init=50, reassignment_ratio=0.0)
Dataset 1 LUNA16: number of data: 842
Dataset 2 Covid 19: OK number of data: 722
Dataset 3 HNSCC: number of data: 954
Dataset 4 TCIA Colon: number of data: 1535
Dataset 5 TCIA LIDC: OK number of data: 450
Dataset all training: number of data: 1535
loader is ready
2023-04-28 11:51:16 | INFO | learn_kmeans | for batch number 0 the res size is 0
2023-04-28 11:54:55 | INFO | learn_kmeans | for batch number 1 the res size is 2304
2023-04-28 11:54:55 | INFO | learn_kmeans | for batch number 2 the res size is 3456
2023-04-28 11:55:56 | INFO | learn_kmeans | for batch number 3 the res size is 4608
2023-04-28 11:55:57 | INFO | learn_kmeans | for batch number 4 the res size is 5760
2023-04-28 11:56:41 | INFO | learn_kmeans | for batch number 5 the res size is 6912
2023-04-28 11:56:41 | INFO | learn_kmeans | for batch number 6 the res size is 8064
2023-04-28 11:56:41 | INFO | learn_kmeans | for batch number 7 the res size is 9216
2023-04-28 11:56:41 | INFO | learn_kmeans | for batch number 8 the res size is 10368
2023-04-28 11:56:42 | INFO | learn_kmeans | for batch number 9 the res size is 11520
2023-04-28 11:56:42 | INFO | learn_kmeans | for batch number 10 the res size is 12672
Traceback (most recent call last):
  File "/home/karimimonsefi.1/SSL_VAN/clustering/kmeans_learning.py", line 145, in <module>
    learn_kmeans(args)
  File "/home/karimimonsefi.1/SSL_VAN/clustering/kmeans_learning.py", line 73, in learn_kmeans
    feat = load_data(args)
  File "/home/karimimonsefi.1/SSL_VAN/clustering/kmeans_learning.py", line 50, in load_data
    for idx, batch_data in enumerate(training_loader):
  File "/home/karimimonsefi.1/miniconda3/lib/python3.9/site-packages/torch/utils/data/dataloader.py", line 628, in __next__
    data = self._next_data()
  File "/home/karimimonsefi.1/miniconda3/lib/python3.9/site-packages/torch/utils/data/dataloader.py", line 1313, in _next_data
    return self._process_data(data)
  File "/home/karimimonsefi.1/miniconda3/lib/python3.9/site-packages/torch/utils/data/dataloader.py", line 1359, in _process_data
    data.reraise()
  File "/home/karimimonsefi.1/miniconda3/lib/python3.9/site-packages/torch/_utils.py", line 543, in reraise
    raise exception
RuntimeError: Caught RuntimeError in DataLoader worker process 11.
Original Traceback (most recent call last):
  File "/home/karimimonsefi.1/miniconda3/lib/python3.9/site-packages/monai/transforms/transform.py", line 89, in apply_transform
    return _apply_transform(transform, data, unpack_items)
  File "/home/karimimonsefi.1/miniconda3/lib/python3.9/site-packages/monai/transforms/transform.py", line 53, in _apply_transform
    return transform(parameters)
  File "/home/karimimonsefi.1/miniconda3/lib/python3.9/site-packages/monai/transforms/io/dictionary.py", line 131, in __call__
    data = self._loader(d[key], reader)
  File "/home/karimimonsefi.1/miniconda3/lib/python3.9/site-packages/monai/transforms/io/array.py", line 240, in __call__
    img_array, meta_data = reader.get_data(img)
  File "/home/karimimonsefi.1/miniconda3/lib/python3.9/site-packages/monai/data/image_reader.py", line 450, in get_data
    data = self._get_array_data(i)
  File "/home/karimimonsefi.1/miniconda3/lib/python3.9/site-packages/monai/data/image_reader.py", line 522, in _get_array_data
    _array = np.array(img.get_fdata(dtype=self.dtype))
  File "/home/karimimonsefi.1/miniconda3/lib/python3.9/site-packages/nibabel/dataobj_images.py", line 368, in get_fdata
    data = np.asanyarray(self._dataobj, dtype=dtype)
  File "/home/karimimonsefi.1/miniconda3/lib/python3.9/site-packages/nibabel/arrayproxy.py", line 426, in __array__
    arr = self._get_scaled(dtype=dtype, slicer=())
  File "/home/karimimonsefi.1/miniconda3/lib/python3.9/site-packages/nibabel/arrayproxy.py", line 393, in _get_scaled
    scaled = apply_read_scaling(self._get_unscaled(slicer=slicer), scl_slope, scl_inter)
  File "/home/karimimonsefi.1/miniconda3/lib/python3.9/site-packages/nibabel/arrayproxy.py", line 363, in _get_unscaled
    return array_from_file(
  File "/home/karimimonsefi.1/miniconda3/lib/python3.9/site-packages/nibabel/volumeutils.py", line 454, in array_from_file
    n_read = infile.readinto(data_bytes)
  File "/home/karimimonsefi.1/miniconda3/lib/python3.9/gzip.py", line 300, in read
    return self._buffer.read(size)
  File "/home/karimimonsefi.1/miniconda3/lib/python3.9/_compression.py", line 68, in readinto
    data = self.read(len(byte_view))
  File "/home/karimimonsefi.1/miniconda3/lib/python3.9/gzip.py", line 495, in read
    uncompress = self._decompressor.decompress(buf, size)
zlib.error: Error -3 while decompressing data: invalid block type

The above exception was the direct cause of the following exception:

Traceback (most recent call last):
  File "/home/karimimonsefi.1/miniconda3/lib/python3.9/site-packages/monai/transforms/transform.py", line 89, in apply_transform
    return _apply_transform(transform, data, unpack_items)
  File "/home/karimimonsefi.1/miniconda3/lib/python3.9/site-packages/monai/transforms/transform.py", line 53, in _apply_transform
    return transform(parameters)
  File "/home/karimimonsefi.1/miniconda3/lib/python3.9/site-packages/monai/transforms/compose.py", line 173, in __call__
    input_ = apply_transform(_transform, input_, self.map_items, self.unpack_items, self.log_stats)
  File "/home/karimimonsefi.1/miniconda3/lib/python3.9/site-packages/monai/transforms/transform.py", line 113, in apply_transform
    raise RuntimeError(f"applying transform {transform}") from e
RuntimeError: applying transform <monai.transforms.io.dictionary.LoadImaged object at 0x15533187cbe0>

The above exception was the direct cause of the following exception:

Traceback (most recent call last):
  File "/home/karimimonsefi.1/miniconda3/lib/python3.9/site-packages/torch/utils/data/_utils/worker.py", line 302, in _worker_loop
    data = fetcher.fetch(index)
  File "/home/karimimonsefi.1/miniconda3/lib/python3.9/site-packages/torch/utils/data/_utils/fetch.py", line 58, in fetch
    data = [self.dataset[idx] for idx in possibly_batched_index]
  File "/home/karimimonsefi.1/miniconda3/lib/python3.9/site-packages/torch/utils/data/_utils/fetch.py", line 58, in <listcomp>
    data = [self.dataset[idx] for idx in possibly_batched_index]
  File "/home/karimimonsefi.1/miniconda3/lib/python3.9/site-packages/monai/data/dataset.py", line 97, in __getitem__
    return self._transform(index)
  File "/home/karimimonsefi.1/miniconda3/lib/python3.9/site-packages/monai/data/dataset.py", line 83, in _transform
    return apply_transform(self.transform, data_i) if self.transform is not None else data_i
  File "/home/karimimonsefi.1/miniconda3/lib/python3.9/site-packages/monai/transforms/transform.py", line 113, in apply_transform
    raise RuntimeError(f"applying transform {transform}") from e
RuntimeError: applying transform <monai.transforms.compose.Compose object at 0x15521daa16d0>

2023-04-28 11:57:06 | INFO | root | Namespace(a_min=-1000, a_max=1000, b_min=0.0, b_max=1.0, space_x=1.5, space_y=1.5, space_z=2.0, roi_x=96, roi_y=96, roi_z=96, num_workers=32, distributed=False, mode='server', num_samples=6, km_path='./cluster_models_1/cluster_model_1_{}_{}_{}.joblib', n_clusters=214, seed=42, init='k-means++', max_iter=250, batch_size=20, tol=0.0, max_no_improvement=100, n_init=50, reassignment_ratio=0.0)
Dataset 1 LUNA16: number of data: 842
Dataset 2 Covid 19: OK number of data: 722
Dataset 3 HNSCC: number of data: 954
Dataset 4 TCIA Colon: number of data: 1535
Dataset 5 TCIA LIDC: OK number of data: 450
Dataset all training: number of data: 1535
loader is ready
2023-04-28 12:06:00 | INFO | learn_kmeans | for batch number 0 the res size is 0
2023-04-28 12:06:03 | INFO | learn_kmeans | for batch number 1 the res size is 2304
2023-04-28 12:06:04 | INFO | learn_kmeans | for batch number 2 the res size is 3456
2023-04-28 12:06:58 | INFO | learn_kmeans | for batch number 3 the res size is 4608
2023-04-28 12:06:59 | INFO | learn_kmeans | for batch number 4 the res size is 5760
2023-04-28 12:06:59 | INFO | learn_kmeans | for batch number 5 the res size is 6912
2023-04-28 12:06:59 | INFO | learn_kmeans | for batch number 6 the res size is 8064
2023-04-28 12:06:59 | INFO | learn_kmeans | for batch number 7 the res size is 9216
2023-04-28 12:06:59 | INFO | learn_kmeans | for batch number 8 the res size is 10368
2023-04-28 12:06:59 | INFO | learn_kmeans | for batch number 9 the res size is 11520
2023-04-28 12:06:59 | INFO | learn_kmeans | for batch number 10 the res size is 12672
2023-04-28 12:07:19 | INFO | learn_kmeans | for batch number 11 the res size is 13824
2023-04-28 12:07:20 | INFO | learn_kmeans | for batch number 12 the res size is 14976
2023-04-28 12:07:20 | INFO | learn_kmeans | for batch number 13 the res size is 16128
2023-04-28 12:07:20 | INFO | learn_kmeans | for batch number 14 the res size is 17280
Traceback (most recent call last):
  File "/home/karimimonsefi.1/SSL_VAN/clustering/kmeans_learning.py", line 145, in <module>
    learn_kmeans(args)
  File "/home/karimimonsefi.1/SSL_VAN/clustering/kmeans_learning.py", line 73, in learn_kmeans
    feat = load_data(args)
  File "/home/karimimonsefi.1/SSL_VAN/clustering/kmeans_learning.py", line 50, in load_data
    for idx, batch_data in enumerate(training_loader):
  File "/home/karimimonsefi.1/miniconda3/lib/python3.9/site-packages/torch/utils/data/dataloader.py", line 628, in __next__
    data = self._next_data()
  File "/home/karimimonsefi.1/miniconda3/lib/python3.9/site-packages/torch/utils/data/dataloader.py", line 1313, in _next_data
    return self._process_data(data)
  File "/home/karimimonsefi.1/miniconda3/lib/python3.9/site-packages/torch/utils/data/dataloader.py", line 1359, in _process_data
    data.reraise()
  File "/home/karimimonsefi.1/miniconda3/lib/python3.9/site-packages/torch/_utils.py", line 543, in reraise
    raise exception
RuntimeError: Caught RuntimeError in DataLoader worker process 15.
Original Traceback (most recent call last):
  File "/home/karimimonsefi.1/miniconda3/lib/python3.9/site-packages/monai/transforms/transform.py", line 89, in apply_transform
    return _apply_transform(transform, data, unpack_items)
  File "/home/karimimonsefi.1/miniconda3/lib/python3.9/site-packages/monai/transforms/transform.py", line 53, in _apply_transform
    return transform(parameters)
  File "/home/karimimonsefi.1/miniconda3/lib/python3.9/site-packages/monai/transforms/io/dictionary.py", line 131, in __call__
    data = self._loader(d[key], reader)
  File "/home/karimimonsefi.1/miniconda3/lib/python3.9/site-packages/monai/transforms/io/array.py", line 240, in __call__
    img_array, meta_data = reader.get_data(img)
  File "/home/karimimonsefi.1/miniconda3/lib/python3.9/site-packages/monai/data/image_reader.py", line 450, in get_data
    data = self._get_array_data(i)
  File "/home/karimimonsefi.1/miniconda3/lib/python3.9/site-packages/monai/data/image_reader.py", line 522, in _get_array_data
    _array = np.array(img.get_fdata(dtype=self.dtype))
  File "/home/karimimonsefi.1/miniconda3/lib/python3.9/site-packages/nibabel/dataobj_images.py", line 368, in get_fdata
    data = np.asanyarray(self._dataobj, dtype=dtype)
  File "/home/karimimonsefi.1/miniconda3/lib/python3.9/site-packages/nibabel/arrayproxy.py", line 426, in __array__
    arr = self._get_scaled(dtype=dtype, slicer=())
  File "/home/karimimonsefi.1/miniconda3/lib/python3.9/site-packages/nibabel/arrayproxy.py", line 393, in _get_scaled
    scaled = apply_read_scaling(self._get_unscaled(slicer=slicer), scl_slope, scl_inter)
  File "/home/karimimonsefi.1/miniconda3/lib/python3.9/site-packages/nibabel/arrayproxy.py", line 363, in _get_unscaled
    return array_from_file(
  File "/home/karimimonsefi.1/miniconda3/lib/python3.9/site-packages/nibabel/volumeutils.py", line 454, in array_from_file
    n_read = infile.readinto(data_bytes)
  File "/home/karimimonsefi.1/miniconda3/lib/python3.9/gzip.py", line 300, in read
    return self._buffer.read(size)
  File "/home/karimimonsefi.1/miniconda3/lib/python3.9/_compression.py", line 68, in readinto
    data = self.read(len(byte_view))
  File "/home/karimimonsefi.1/miniconda3/lib/python3.9/gzip.py", line 495, in read
    uncompress = self._decompressor.decompress(buf, size)
zlib.error: Error -3 while decompressing data: invalid block type

The above exception was the direct cause of the following exception:

Traceback (most recent call last):
  File "/home/karimimonsefi.1/miniconda3/lib/python3.9/site-packages/monai/transforms/transform.py", line 89, in apply_transform
    return _apply_transform(transform, data, unpack_items)
  File "/home/karimimonsefi.1/miniconda3/lib/python3.9/site-packages/monai/transforms/transform.py", line 53, in _apply_transform
    return transform(parameters)
  File "/home/karimimonsefi.1/miniconda3/lib/python3.9/site-packages/monai/transforms/compose.py", line 173, in __call__
    input_ = apply_transform(_transform, input_, self.map_items, self.unpack_items, self.log_stats)
  File "/home/karimimonsefi.1/miniconda3/lib/python3.9/site-packages/monai/transforms/transform.py", line 113, in apply_transform
    raise RuntimeError(f"applying transform {transform}") from e
RuntimeError: applying transform <monai.transforms.io.dictionary.LoadImaged object at 0x147a53081be0>

The above exception was the direct cause of the following exception:

Traceback (most recent call last):
  File "/home/karimimonsefi.1/miniconda3/lib/python3.9/site-packages/torch/utils/data/_utils/worker.py", line 302, in _worker_loop
    data = fetcher.fetch(index)
  File "/home/karimimonsefi.1/miniconda3/lib/python3.9/site-packages/torch/utils/data/_utils/fetch.py", line 58, in fetch
    data = [self.dataset[idx] for idx in possibly_batched_index]
  File "/home/karimimonsefi.1/miniconda3/lib/python3.9/site-packages/torch/utils/data/_utils/fetch.py", line 58, in <listcomp>
    data = [self.dataset[idx] for idx in possibly_batched_index]
  File "/home/karimimonsefi.1/miniconda3/lib/python3.9/site-packages/monai/data/dataset.py", line 97, in __getitem__
    return self._transform(index)
  File "/home/karimimonsefi.1/miniconda3/lib/python3.9/site-packages/monai/data/dataset.py", line 83, in _transform
    return apply_transform(self.transform, data_i) if self.transform is not None else data_i
  File "/home/karimimonsefi.1/miniconda3/lib/python3.9/site-packages/monai/transforms/transform.py", line 113, in apply_transform
    raise RuntimeError(f"applying transform {transform}") from e
RuntimeError: applying transform <monai.transforms.compose.Compose object at 0x14793f2a7610>

2023-04-28 12:07:52 | INFO | root | Namespace(a_min=-1000, a_max=1000, b_min=0.0, b_max=1.0, space_x=1.5, space_y=1.5, space_z=2.0, roi_x=96, roi_y=96, roi_z=96, num_workers=32, distributed=False, mode='server', num_samples=6, km_path='./cluster_models_1/cluster_model_1_{}_{}_{}.joblib', n_clusters=481, seed=42, init='k-means++', max_iter=250, batch_size=20, tol=0.0, max_no_improvement=100, n_init=50, reassignment_ratio=0.0)
Dataset 1 LUNA16: number of data: 842
Dataset 2 Covid 19: OK number of data: 722
Dataset 3 HNSCC: number of data: 954
Dataset 4 TCIA Colon: number of data: 1535
Dataset 5 TCIA LIDC: OK number of data: 450
Dataset all training: number of data: 1535
loader is ready
2023-04-28 12:16:41 | INFO | learn_kmeans | for batch number 0 the res size is 0
2023-04-28 12:16:42 | INFO | learn_kmeans | for batch number 1 the res size is 2304
2023-04-28 12:16:42 | INFO | learn_kmeans | for batch number 2 the res size is 3456
2023-04-28 12:17:04 | INFO | learn_kmeans | for batch number 3 the res size is 4608
2023-04-28 12:17:05 | INFO | learn_kmeans | for batch number 4 the res size is 5760
2023-04-28 12:17:05 | INFO | learn_kmeans | for batch number 5 the res size is 6912
2023-04-28 12:17:28 | INFO | learn_kmeans | for batch number 6 the res size is 8064
2023-04-28 12:17:28 | INFO | learn_kmeans | for batch number 7 the res size is 9216
2023-04-28 12:17:28 | INFO | learn_kmeans | for batch number 8 the res size is 10368
2023-04-28 12:17:28 | INFO | learn_kmeans | for batch number 9 the res size is 11520
2023-04-28 12:17:28 | INFO | learn_kmeans | for batch number 10 the res size is 12672
2023-04-28 12:17:28 | INFO | learn_kmeans | for batch number 11 the res size is 13824
2023-04-28 12:17:28 | INFO | learn_kmeans | for batch number 12 the res size is 14976
2023-04-28 12:17:28 | INFO | learn_kmeans | for batch number 13 the res size is 16128
2023-04-28 12:17:28 | INFO | learn_kmeans | for batch number 14 the res size is 17280
2023-04-28 12:17:28 | INFO | learn_kmeans | for batch number 15 the res size is 18432
Traceback (most recent call last):
  File "/home/karimimonsefi.1/SSL_VAN/clustering/kmeans_learning.py", line 145, in <module>
    learn_kmeans(args)
  File "/home/karimimonsefi.1/SSL_VAN/clustering/kmeans_learning.py", line 73, in learn_kmeans
    feat = load_data(args)
  File "/home/karimimonsefi.1/SSL_VAN/clustering/kmeans_learning.py", line 50, in load_data
    for idx, batch_data in enumerate(training_loader):
  File "/home/karimimonsefi.1/miniconda3/lib/python3.9/site-packages/torch/utils/data/dataloader.py", line 628, in __next__
    data = self._next_data()
  File "/home/karimimonsefi.1/miniconda3/lib/python3.9/site-packages/torch/utils/data/dataloader.py", line 1313, in _next_data
    return self._process_data(data)
  File "/home/karimimonsefi.1/miniconda3/lib/python3.9/site-packages/torch/utils/data/dataloader.py", line 1359, in _process_data
    data.reraise()
  File "/home/karimimonsefi.1/miniconda3/lib/python3.9/site-packages/torch/_utils.py", line 543, in reraise
    raise exception
RuntimeError: Caught RuntimeError in DataLoader worker process 16.
Original Traceback (most recent call last):
  File "/home/karimimonsefi.1/miniconda3/lib/python3.9/site-packages/monai/transforms/transform.py", line 89, in apply_transform
    return _apply_transform(transform, data, unpack_items)
  File "/home/karimimonsefi.1/miniconda3/lib/python3.9/site-packages/monai/transforms/transform.py", line 53, in _apply_transform
    return transform(parameters)
  File "/home/karimimonsefi.1/miniconda3/lib/python3.9/site-packages/monai/transforms/io/dictionary.py", line 131, in __call__
    data = self._loader(d[key], reader)
  File "/home/karimimonsefi.1/miniconda3/lib/python3.9/site-packages/monai/transforms/io/array.py", line 240, in __call__
    img_array, meta_data = reader.get_data(img)
  File "/home/karimimonsefi.1/miniconda3/lib/python3.9/site-packages/monai/data/image_reader.py", line 450, in get_data
    data = self._get_array_data(i)
  File "/home/karimimonsefi.1/miniconda3/lib/python3.9/site-packages/monai/data/image_reader.py", line 522, in _get_array_data
    _array = np.array(img.get_fdata(dtype=self.dtype))
  File "/home/karimimonsefi.1/miniconda3/lib/python3.9/site-packages/nibabel/dataobj_images.py", line 368, in get_fdata
    data = np.asanyarray(self._dataobj, dtype=dtype)
  File "/home/karimimonsefi.1/miniconda3/lib/python3.9/site-packages/nibabel/arrayproxy.py", line 426, in __array__
    arr = self._get_scaled(dtype=dtype, slicer=())
  File "/home/karimimonsefi.1/miniconda3/lib/python3.9/site-packages/nibabel/arrayproxy.py", line 393, in _get_scaled
    scaled = apply_read_scaling(self._get_unscaled(slicer=slicer), scl_slope, scl_inter)
  File "/home/karimimonsefi.1/miniconda3/lib/python3.9/site-packages/nibabel/arrayproxy.py", line 363, in _get_unscaled
    return array_from_file(
  File "/home/karimimonsefi.1/miniconda3/lib/python3.9/site-packages/nibabel/volumeutils.py", line 454, in array_from_file
    n_read = infile.readinto(data_bytes)
  File "/home/karimimonsefi.1/miniconda3/lib/python3.9/gzip.py", line 300, in read
    return self._buffer.read(size)
  File "/home/karimimonsefi.1/miniconda3/lib/python3.9/_compression.py", line 68, in readinto
    data = self.read(len(byte_view))
  File "/home/karimimonsefi.1/miniconda3/lib/python3.9/gzip.py", line 495, in read
    uncompress = self._decompressor.decompress(buf, size)
zlib.error: Error -3 while decompressing data: invalid block type

The above exception was the direct cause of the following exception:

Traceback (most recent call last):
  File "/home/karimimonsefi.1/miniconda3/lib/python3.9/site-packages/monai/transforms/transform.py", line 89, in apply_transform
    return _apply_transform(transform, data, unpack_items)
  File "/home/karimimonsefi.1/miniconda3/lib/python3.9/site-packages/monai/transforms/transform.py", line 53, in _apply_transform
    return transform(parameters)
  File "/home/karimimonsefi.1/miniconda3/lib/python3.9/site-packages/monai/transforms/compose.py", line 173, in __call__
    input_ = apply_transform(_transform, input_, self.map_items, self.unpack_items, self.log_stats)
  File "/home/karimimonsefi.1/miniconda3/lib/python3.9/site-packages/monai/transforms/transform.py", line 113, in apply_transform
    raise RuntimeError(f"applying transform {transform}") from e
RuntimeError: applying transform <monai.transforms.io.dictionary.LoadImaged object at 0x14ba2a146be0>

The above exception was the direct cause of the following exception:

Traceback (most recent call last):
  File "/home/karimimonsefi.1/miniconda3/lib/python3.9/site-packages/torch/utils/data/_utils/worker.py", line 302, in _worker_loop
    data = fetcher.fetch(index)
  File "/home/karimimonsefi.1/miniconda3/lib/python3.9/site-packages/torch/utils/data/_utils/fetch.py", line 58, in fetch
    data = [self.dataset[idx] for idx in possibly_batched_index]
  File "/home/karimimonsefi.1/miniconda3/lib/python3.9/site-packages/torch/utils/data/_utils/fetch.py", line 58, in <listcomp>
    data = [self.dataset[idx] for idx in possibly_batched_index]
  File "/home/karimimonsefi.1/miniconda3/lib/python3.9/site-packages/monai/data/dataset.py", line 97, in __getitem__
    return self._transform(index)
  File "/home/karimimonsefi.1/miniconda3/lib/python3.9/site-packages/monai/data/dataset.py", line 83, in _transform
    return apply_transform(self.transform, data_i) if self.transform is not None else data_i
  File "/home/karimimonsefi.1/miniconda3/lib/python3.9/site-packages/monai/transforms/transform.py", line 113, in apply_transform
    raise RuntimeError(f"applying transform {transform}") from e
RuntimeError: applying transform <monai.transforms.compose.Compose object at 0x14b91636b610>

2023-04-28 12:18:11 | INFO | root | Namespace(a_min=-1000, a_max=1000, b_min=0.0, b_max=1.0, space_x=1.5, space_y=1.5, space_z=2.0, roi_x=96, roi_y=96, roi_z=96, num_workers=32, distributed=False, mode='server', num_samples=6, km_path='./cluster_models_1/cluster_model_1_{}_{}_{}.joblib', n_clusters=499, seed=42, init='k-means++', max_iter=250, batch_size=20, tol=0.0, max_no_improvement=100, n_init=50, reassignment_ratio=0.0)
Dataset 1 LUNA16: number of data: 842
Dataset 2 Covid 19: OK number of data: 722
Dataset 3 HNSCC: number of data: 954
Dataset 4 TCIA Colon: number of data: 1535
Dataset 5 TCIA LIDC: OK number of data: 450
Dataset all training: number of data: 1535
loader is ready
2023-04-28 12:19:39 | INFO | learn_kmeans | for batch number 0 the res size is 0
2023-04-28 12:25:05 | INFO | learn_kmeans | for batch number 1 the res size is 2304
2023-04-28 12:26:05 | INFO | learn_kmeans | for batch number 2 the res size is 3456
2023-04-28 12:26:06 | INFO | learn_kmeans | for batch number 3 the res size is 4608
2023-04-28 12:27:40 | INFO | learn_kmeans | for batch number 4 the res size is 5760
2023-04-28 12:27:40 | INFO | learn_kmeans | for batch number 5 the res size is 6912
2023-04-28 12:27:40 | INFO | learn_kmeans | for batch number 6 the res size is 8064
2023-04-28 12:27:40 | INFO | learn_kmeans | for batch number 7 the res size is 9216
2023-04-28 12:27:40 | INFO | learn_kmeans | for batch number 8 the res size is 10368
2023-04-28 12:27:40 | INFO | learn_kmeans | for batch number 9 the res size is 11520
2023-04-28 12:27:40 | INFO | learn_kmeans | for batch number 10 the res size is 12672
2023-04-28 12:27:41 | INFO | learn_kmeans | for batch number 11 the res size is 13824
2023-04-28 12:27:41 | INFO | learn_kmeans | for batch number 12 the res size is 14976
2023-04-28 12:27:41 | INFO | learn_kmeans | for batch number 13 the res size is 16128
2023-04-28 12:27:41 | INFO | learn_kmeans | for batch number 14 the res size is 17280
2023-04-28 12:27:41 | INFO | learn_kmeans | for batch number 15 the res size is 18432
2023-04-28 12:27:50 | INFO | learn_kmeans | for batch number 16 the res size is 19584
2023-04-28 12:27:50 | INFO | learn_kmeans | for batch number 17 the res size is 20736
2023-04-28 12:27:50 | INFO | learn_kmeans | for batch number 18 the res size is 21888
2023-04-28 12:27:50 | INFO | learn_kmeans | for batch number 19 the res size is 23040
2023-04-28 12:27:50 | INFO | learn_kmeans | for batch number 20 the res size is 24192
2023-04-28 12:27:50 | INFO | learn_kmeans | for batch number 21 the res size is 25344
Traceback (most recent call last):
  File "/home/karimimonsefi.1/SSL_VAN/clustering/kmeans_learning.py", line 145, in <module>
    learn_kmeans(args)
  File "/home/karimimonsefi.1/SSL_VAN/clustering/kmeans_learning.py", line 73, in learn_kmeans
    feat = load_data(args)
  File "/home/karimimonsefi.1/SSL_VAN/clustering/kmeans_learning.py", line 50, in load_data
    for idx, batch_data in enumerate(training_loader):
  File "/home/karimimonsefi.1/miniconda3/lib/python3.9/site-packages/torch/utils/data/dataloader.py", line 628, in __next__
    data = self._next_data()
  File "/home/karimimonsefi.1/miniconda3/lib/python3.9/site-packages/torch/utils/data/dataloader.py", line 1313, in _next_data
    return self._process_data(data)
  File "/home/karimimonsefi.1/miniconda3/lib/python3.9/site-packages/torch/utils/data/dataloader.py", line 1359, in _process_data
    data.reraise()
  File "/home/karimimonsefi.1/miniconda3/lib/python3.9/site-packages/torch/_utils.py", line 543, in reraise
    raise exception
RuntimeError: Caught RuntimeError in DataLoader worker process 22.
Original Traceback (most recent call last):
  File "/home/karimimonsefi.1/miniconda3/lib/python3.9/site-packages/monai/transforms/transform.py", line 89, in apply_transform
    return _apply_transform(transform, data, unpack_items)
  File "/home/karimimonsefi.1/miniconda3/lib/python3.9/site-packages/monai/transforms/transform.py", line 53, in _apply_transform
    return transform(parameters)
  File "/home/karimimonsefi.1/miniconda3/lib/python3.9/site-packages/monai/transforms/io/dictionary.py", line 131, in __call__
    data = self._loader(d[key], reader)
  File "/home/karimimonsefi.1/miniconda3/lib/python3.9/site-packages/monai/transforms/io/array.py", line 240, in __call__
    img_array, meta_data = reader.get_data(img)
  File "/home/karimimonsefi.1/miniconda3/lib/python3.9/site-packages/monai/data/image_reader.py", line 450, in get_data
    data = self._get_array_data(i)
  File "/home/karimimonsefi.1/miniconda3/lib/python3.9/site-packages/monai/data/image_reader.py", line 522, in _get_array_data
    _array = np.array(img.get_fdata(dtype=self.dtype))
  File "/home/karimimonsefi.1/miniconda3/lib/python3.9/site-packages/nibabel/dataobj_images.py", line 368, in get_fdata
    data = np.asanyarray(self._dataobj, dtype=dtype)
  File "/home/karimimonsefi.1/miniconda3/lib/python3.9/site-packages/nibabel/arrayproxy.py", line 426, in __array__
    arr = self._get_scaled(dtype=dtype, slicer=())
  File "/home/karimimonsefi.1/miniconda3/lib/python3.9/site-packages/nibabel/arrayproxy.py", line 393, in _get_scaled
    scaled = apply_read_scaling(self._get_unscaled(slicer=slicer), scl_slope, scl_inter)
  File "/home/karimimonsefi.1/miniconda3/lib/python3.9/site-packages/nibabel/arrayproxy.py", line 363, in _get_unscaled
    return array_from_file(
  File "/home/karimimonsefi.1/miniconda3/lib/python3.9/site-packages/nibabel/volumeutils.py", line 454, in array_from_file
    n_read = infile.readinto(data_bytes)
  File "/home/karimimonsefi.1/miniconda3/lib/python3.9/gzip.py", line 300, in read
    return self._buffer.read(size)
  File "/home/karimimonsefi.1/miniconda3/lib/python3.9/_compression.py", line 68, in readinto
    data = self.read(len(byte_view))
  File "/home/karimimonsefi.1/miniconda3/lib/python3.9/gzip.py", line 506, in read
    raise EOFError("Compressed file ended before the "
EOFError: Compressed file ended before the end-of-stream marker was reached

The above exception was the direct cause of the following exception:

Traceback (most recent call last):
  File "/home/karimimonsefi.1/miniconda3/lib/python3.9/site-packages/monai/transforms/transform.py", line 89, in apply_transform
    return _apply_transform(transform, data, unpack_items)
  File "/home/karimimonsefi.1/miniconda3/lib/python3.9/site-packages/monai/transforms/transform.py", line 53, in _apply_transform
    return transform(parameters)
  File "/home/karimimonsefi.1/miniconda3/lib/python3.9/site-packages/monai/transforms/compose.py", line 173, in __call__
    input_ = apply_transform(_transform, input_, self.map_items, self.unpack_items, self.log_stats)
  File "/home/karimimonsefi.1/miniconda3/lib/python3.9/site-packages/monai/transforms/transform.py", line 113, in apply_transform
    raise RuntimeError(f"applying transform {transform}") from e
RuntimeError: applying transform <monai.transforms.io.dictionary.LoadImaged object at 0x14cfcdd60be0>

The above exception was the direct cause of the following exception:

Traceback (most recent call last):
  File "/home/karimimonsefi.1/miniconda3/lib/python3.9/site-packages/torch/utils/data/_utils/worker.py", line 302, in _worker_loop
    data = fetcher.fetch(index)
  File "/home/karimimonsefi.1/miniconda3/lib/python3.9/site-packages/torch/utils/data/_utils/fetch.py", line 58, in fetch
    data = [self.dataset[idx] for idx in possibly_batched_index]
  File "/home/karimimonsefi.1/miniconda3/lib/python3.9/site-packages/torch/utils/data/_utils/fetch.py", line 58, in <listcomp>
    data = [self.dataset[idx] for idx in possibly_batched_index]
  File "/home/karimimonsefi.1/miniconda3/lib/python3.9/site-packages/monai/data/dataset.py", line 97, in __getitem__
    return self._transform(index)
  File "/home/karimimonsefi.1/miniconda3/lib/python3.9/site-packages/monai/data/dataset.py", line 83, in _transform
    return apply_transform(self.transform, data_i) if self.transform is not None else data_i
  File "/home/karimimonsefi.1/miniconda3/lib/python3.9/site-packages/monai/transforms/transform.py", line 113, in apply_transform
    raise RuntimeError(f"applying transform {transform}") from e
RuntimeError: applying transform <monai.transforms.compose.Compose object at 0x14ceb9f84610>

2023-04-28 12:28:11 | INFO | root | Namespace(a_min=-1000, a_max=1000, b_min=0.0, b_max=1.0, space_x=1.5, space_y=1.5, space_z=2.0, roi_x=96, roi_y=96, roi_z=96, num_workers=32, distributed=False, mode='server', num_samples=6, km_path='./cluster_models_1/cluster_model_1_{}_{}_{}.joblib', n_clusters=387, seed=42, init='k-means++', max_iter=250, batch_size=20, tol=0.0, max_no_improvement=100, n_init=50, reassignment_ratio=0.0)
Dataset 1 LUNA16: number of data: 842
Dataset 2 Covid 19: OK number of data: 722
Dataset 3 HNSCC: number of data: 954
Dataset 4 TCIA Colon: number of data: 1535
Dataset 5 TCIA LIDC: OK number of data: 450
Dataset all training: number of data: 1535
loader is ready
slurmstepd: error: *** JOB 50734 ON a100-01 CANCELLED AT 2023-04-28T12:33:28 DUE TO TIME LIMIT ***
